Workbook

Sheet 填写说明
A1: 经销商生意健康度诊断 - 定量指标填写指南
A2: 致各位合作伙伴： 为确保本次生意健康度诊断的公平、公正与准确，请您在填写各项数据时，严格参考以下指标的统计口径、单位与说明
A3: 维度 | B3: 指标名称 | C3: 单位 | D3: 计算公式 / 统计口径 | E3: 填写须知
A4: 业绩 | B4: 合同达成率 | C4: % | D4: 合同达成率=本年度实际销售额 ÷ 本年度合同任务额 | E4: 按百分比填写，保留1位小数。
B5: 销售增长率 | C5: % | D5: 销售增长率 =（本年度实际销售额 − 上年度实际销售额）÷ 上年度实际销售额 | E5: 同上。
A6: 分销 | B6: 网点数量 | C6: 个 | D6: 过去12个月内，与贵公司有过至少一次交易记录的下游门店、分销商总数 | E6: 填整数，单位个。
B7: 核心店占比 | C7: % | D7: 核心店占比=核心门店数 ÷ 网点数量 × 100% | E7: 核心店包括核心形象店和核心分销店 请填写最终比例值，填写范围0～1，按百分比填写，保留1位小数。
B8: 单店产出 | C8: 万元 | D8: 单店产出=全年雨虹分销渠道总销售额 ÷ 网点数量 | E8: 销售额按雨虹业务口径。保留1位小数。
B9: 有效门店占比 | C9: % | D9: 有效门店占比=(有效门店数 ÷ 网点数量) × 100% | E9: 有效门店：指三个月内存在拜访记录，陈列合格上报的门店 请填写最终比例值，填写范围0～1，按百分比填写，保留1位小数。
B10: 人均服务网点数 | C10: 个/人 | D10: 人均服务网点数=网点数量 ÷ (自有销售人员数量 × 雨虹销售额占比 + 虹销员数量) | E10: 自有销售人员数量需按雨虹销售额占比折算（参见自有人员数量指标说明）；虹销员不需折算。
B11: 自有人员数量 | C11: 人 | D11: 由贵公司全职聘用、发放薪酬，且主要职责为销售的人员数量。若同时经营多品牌，后续指标计算时将按雨虹销售额占比折算 | E11: 不包括仓管、物流等非销售岗。虹销员不计入此项。 多品牌经营者：请如实填写自有销售人员总数，指标计算时将以「雨虹业务销售额 ÷ 总销售额」占比进行折算，消除多品牌经营导致的评分偏差。
B12: 人效 | C12: 万元/人 | D12: 人效=全年雨虹业务总销售额 ÷ (自有销售人员数量 × 雨虹销售额占比 + 虹销员数量) | E12: 分子：全年雨虹业务总销售额（非总销售额），按雨虹口径。 分母：自有销售人员数量需按雨虹销售额占比折算；虹销员不需折算。保留1位小数。
B13: 乡镇覆盖率 | C13: % | D13: 乡镇覆盖率=(已覆盖的乡镇/街道数量 ÷ 授权区域内乡镇/街道总数)× 100% | E13: 按百分比填写，保留1位小数。
A14: 零售 | B14: 会员数量 | C14: 人 | D14: 在会员系统正式注册的工长/师傅数量 | E14: /
B15: 会员人均产出 | C15: 万元/人 | D15: 会员人均产出=全年雨虹零售渠道总销售额 ÷ 会员数量 | E15: 销售额按雨虹零售渠道口径。保留2位小数。
A16: 渠道结构 | B16: 渠道均衡发展 | C16: 个 | D16: 贵公司目前重点经营的渠道数量 | E16: 例如，同时经营分销、零售、家装，则填写“3”。
A17: 品类结构 | B17: 品类均衡发展 | C17: 个 | D17: 贵公司目前稳定经营的雨虹品类数量 | E17: 品类包括防水、砂浆、美缝、胶业、卷材、辅材。
A18: 公司运营 | B18: 坪效 | C18: 万元/平方米 | D18: 坪效=全年雨虹业务总销售额 ÷ 仓库中专门用于存储雨虹产品的面积 | E18: 仓库面积严格按雨虹产品实际存储面积计算，不含其他品牌产品存放区域。若仓库为多品牌共用，请按雨虹产品实际占用面积填写。保留2位小数。
B19: 分销会次数 | C19: 次 | D19: 过去12个月内，由贵公司主导组织的面向下游分销商的会议总次数 | E19: /
B20: 专业人士会议次数 | C20: 次 | D20: 过去12个月内，由贵公司主导组织的面向工长/设计师等专业人士的会议总次数 | E20: 例如瓦工会、油工会、设计师沙龙等。
B21: 数字化水平 | C21: 等级（a/b/c/d) | D21: 请根据标准，选择最符合贵公司现状的等级 | E21: a.仅拥有进销存数字化系统水平； b.能够进行数据分析水平； c.具有数字化指标洞察水平； d.尚未采用数字化系统
A22: 意愿度 | B22: 活动参与度 | C22: 等级（a/b/c) | D22: 请根据标准，选择最符合贵公司现状的等级 | E22: a：积极参与品牌方（YH）日常会议、培训、活动，并表现突出 b：参与品牌方（YH）日常会议、培训、活动，较少存在请假、早退等情况 c：基本不参与品牌方（YH）日常会议、培训、活动
B23: 经营意愿 | D23: 请根据标准，选择最符合贵公司现状的等级 | E23: a：对于YH品牌存在巨大经营信心，积极与品牌方（YH）互动沟通，每周不少于1次同品牌方（YH）开展经营沟通，愿意配合品牌方（YH）积极开展市场活动，并投入人力物力等资源开展经营 b：对于YH品牌存在经营信心，较为配合执行品牌方（YH）市场活动政策 c：计划放弃经营YH品牌（指经销商解约），不配合品牌方（YH）日常管理，不协助品牌方（YH）执行市场活动政策
B24: 文化认知度 | D24: 请根据标准，选择最符合贵公司现状的等级 | E24: a：对于东方雨虹企业文化存在清晰认知，认同东方雨虹企业文化，并在日常市场经营活动中积极践行 b：清楚了解东方雨虹企业文化，对于东方雨虹企业文化存在认同 c：不清楚东方雨虹企业文化，不认同东方雨虹企业文化
A26: 附加分指标计算口径说明
A27: 维度 | B27: 指标名称 | C27: 单位 | D27: 计算公式 / 统计口径 | E27: 填写须知
A28: 分销 | B28: 网点覆盖率 | C28: % | D28: 网点覆盖率 = 实际覆盖网点数 ÷ 区域内目标网点总数 | E28: 填小数，如覆盖率90%填 0.9，无需保留小数
B29: 网点活跃度 | C29: % | D29: 网点活跃度 = 近3个月内有进货记录的网点数 ÷ 网点总数 | E29: 填小数，如活跃度45%填 0.45，无需保留小数
A30: 零售 | B30: 会员活跃率 | C30: % | D30: 会员活跃率 = 近3个月内有消费记录的会员数 ÷ 会员总数 | E30: 填小数，如活跃率30%填 0.3，无需保留小数
A31: 家装 | B31: 家装销售占比 | C31: % | D31: 家装销售占比 = 全年家装渠道总销售额 ÷ 全年所有渠道总销售额 | E31: 填小数，如占比2.70%填 0.027，保留2位小数
B32: 月均家装订单数 | C32: 户 | D32: 月均家装订单数 = 全年家装渠道订单总数 ÷ 12 | E32: 填整数，计算结果有小数四舍五入
B33: 家装公司产出/月 | C33: 元 | D33: 单家家装公司月均产出 = 全年家装渠道总销售额 ÷ 合作家装公司总数 ÷ 12 | E33: 填整数，单位为元
A34: 服务 | B34: 工单转化率 | C34: 单 | D34: 工单转化率 = 已转化工单数 ÷ 总工单数 × 100% | E34: 填小数，如转化率45%填 0.45，无需保留小数
B35: 月均工单数量 | C35: 单 | D35: 月均工单数量 = 全年服务业务总工单数 ÷ 12 | E35: 填整数，计算结果有小数四舍五入
A36: 公司维度 | B36: 人效 | C36: 万/人 | D36: 人效 = 全年总销售额 ÷（自有销售人员数量 + 虹销员数量） | E36: 填数值，单位万元/人，保留2位小数
A39: 区域外部市场分析指标填写说明
A40: 维度 | B40: 指标名称 | C40: 单位 | D40: 计算公式 / 统计口径 | E40: 填写须知
A41: 区域市场竞争格局诊断 | B41: 雨虹年度销售额 | C41: 万元 | D41: 本区域雨虹品牌全渠道全年实际销售额 | E41: 填整数，单位万元
B42: 各竞品年度销售额 | C42: 万元 | D42: 德高、立邦及其他主要竞品在本区域的年度预估销售额 | E42: 填整数，单位万元，不清楚可填估算值，无竞品留空即可
B43: 我方市占率 | C43: % | D43: 我方市占率 = 雨虹年度销售额 ÷ 所有品牌销售额合计 × 100% | E43: 自动计算，无需填写，请勿修改此单元格
...

Sheet 动态诊断表
B1: 经销商生意诊断表
B2: 城市等级 | D2: 三四级 | G2: 商体量 | H2: 1000W-2000W | J2: 说明：通过筛选城市等级/商体量，调用对应数据；红色指标为重要性指标；白色为填写区。
A3: 定量指标参考值 | P3: 附加分指标参考值 | Y3: 区域外部市场分析
A5: 维度 | D5: 指标 | E5: 权重 | F5: 函数项 | G5: 实际值 | H5: 得分 | I5: 优秀值 | J5: 指标 | K5: 权重 | L5: 函数项 | M5: 实际值 | N5: 得分 | O5: 优秀值 | P5: 渠道维度 | Q5: 指标 | S5: 权重 | T5: 函数项 | U5: 实际值 | W5: 得分 | X5: 优秀值 | Y5: 1. 市场容量与份额分析
A6: 增长层 | B6: 渠道维度 | C6: 生意总体 | D6: 合同达成率（%） | E6: =INDEX(数据底稿1!$G:$G,MATCH($D$2&"|"&$H$2&"|合同达成率",数据底稿1!$Z:$Z,0)) -> 0.1 | F6: =IF(G6<=INDEX(数据底稿1!$I:$I,MATCH($D$2&"|"&$H$2&"|合同达成率",数据底稿1!$Z:$Z,0)),G6*INDEX(数据底稿1!$J:$J,MATCH($D$2&"|"&$H$2&"|合同达成率",数据底稿1!$Z:$Z,0)),IF(G6<=INDEX(数据底稿1!$M:$M,MATCH($D$2&"|"&$H$2&"|合同达成率",数据底稿1!$Z:$Z,0)),G6*INDEX(数据底稿1!$N:$N,MATCH($D$2&"|"&$H$2&"|合同达成率",数据底稿1!$Z:$Z,0)),IF(G6<=INDEX(数据底稿1!$Q:$Q,MATCH($D$2&"|"&$H$2&"|合同达成率",数据底稿1!$Z:$Z,0)),G6*INDEX(数据底稿1!$R:$R,MATCH($D$2&"|"&$H$2&"|合同达成率",数据底稿1!$Z:$Z,0)),INDEX(数据底稿1!$V:$V,MATCH($D$2&"|"&$H$2&"|合同达成率",数据底稿1!$Z:$Z,0))))) -> 0.144 | G6: 1 | H6: =IF(ISBLANK(G6),"",F6*100) -> 14.4 | I6: =IFERROR(TEXT(INDEX(数据底稿1!$H:$H,MATCH($D$2&"|"&$H$2&"|合同达成率",数据底稿1!$Z:$Z,0)),"0.0%"),INDEX(数据底稿1!$H:$H,MATCH($D$2&"|"&$H$2&"|合同达成率",数据底稿1!$Z:$Z,0))) -> 100.0% | J6: 销售增长率（%） | K6: =INDEX(数据底稿1!$G:$G,MATCH($D$2&"|"&$H$2&"|销售增长率",数据底稿1!$Z:$Z,0)) -> 0.1 | L6: =IF(M6<INDEX(数据底稿1!$I:$I,MATCH($D$2&"|"&$H$2&"|销售增长率",数据底稿1!$Z:$Z,0)),INDEX(数据底稿1!$J:$J,MATCH($D$2&"|"&$H$2&"|销售增长率",数据底稿1!$Z:$Z,0)),IF(M6<INDEX(数据底稿1!$M:$M,MATCH($D$2&"|"&$H$2&"|销售增长率",数据底稿1!$Z:$Z,0)),INDEX(数据底稿1!$N:$N,MATCH($D$2&"|"&$H$2&"|销售增长率",数据底稿1!$Z:$Z,0)),IF(M6<INDEX(数据底稿1!$Q:$Q,MATCH($D$2&"|"&$H$2&"|销售增长率",数据底稿1!$Z:$Z,0)),INDEX(数据底稿1!$R:$R,MATCH($D$2&"|"&$H$2&"|销售增长率",数据底稿1!$Z:$Z,0)),INDEX(数据底稿1!$V:$V,MATCH($D$2&"|"&$H$2&"|销售增长率",数据底稿1!$Z:$Z,0))))) -> 0.1 | M6: 0.3 | N6: =IF(ISBLANK(M6),"",L6*100) -> 10 | O6: =IFERROR(TEXT(INDEX(数据底稿1!$H:$H,MATCH($D$2&"|"&$H$2&"|销售增长率",数据底稿1!$Z:$Z,0)),"0.0%"),INDEX(数据底稿1!$H:$H,MATCH($D$2&"|"&$H$2&"|销售增长率",数据底稿1!$Z:$Z,0))) -> 15.1% | P6: 零售 | Q6: 会员活跃率 | S6: 0.25 | T6: =IF(U6="","",IF(U6>=INDEX(数据底稿2!C4:K4,1,MATCH($D$2&$H$2,数据底稿2!$C$3:$K$3,0)),90,IF(U6>=INDEX(数据底稿2!C5:K5,1,MATCH($D$2&$H$2,数据底稿2!$C$3:$K$3,0)),70,IF(U6>=INDEX(数据底稿2!C6:K6,1,MATCH($D$2&$H$2,数据底稿2!$C$3:$K$3,0)),50,30)))) -> 70 | U6: 0.1 | W6: =IF(U6="","",T6*S6) -> 17.5 | X6: =INDEX(数据底稿2!C4:K4,1,MATCH($D$2&$H$2,数据底稿2!$C$3:$K$3,0)) -> 0.1318 | Y6: 选择品类 | AA6: 防水
C7: 分销 | D7: 网点数量（个） | E7: =INDEX(数据底稿1!$G:$G,MATCH($D$2&"|"&$H$2&"|网点数量",数据底稿1!$Z:$Z,0)) -> 0.041 | F7: =IF(G7<INDEX(数据底稿1!$I:$I,MATCH($D$2&"|"&$H$2&"|网点数量",数据底稿1!$Z:$Z,0)),INDEX(数据底稿1!$J:$J,MATCH($D$2&"|"&$H$2&"|网点数量",数据底稿1!$Z:$Z,0)),IF(G7<INDEX(数据底稿1!$M:$M,MATCH($D$2&"|"&$H$2&"|网点数量",数据底稿1!$Z:$Z,0)),INDEX(数据底稿1!$N:$N,MATCH($D$2&"|"&$H$2&"|网点数量",数据底稿1!$Z:$Z,0)),IF(INDEX(数据底稿1!$Q:$Q,MATCH($D$2&"|"&$H$2&"|网点数量",数据底稿1!$Z:$Z,0))="",INDEX(数据底稿1!$R:$R,MATCH($D$2&"|"&$H$2&"|网点数量",数据底稿1!$Z:$Z,0)),IF(G7<INDEX(数据底稿1!$Q:$Q,MATCH($D$2&"|"&$H$2&"|网点数量",数据底稿1!$Z:$Z,0)),INDEX(数据底稿1!$R:$R,MATCH($D$2&"|"&$H$2&"|网点数量",数据底稿1!$Z:$Z,0)),IF(INDEX(数据底稿1!$V:$V,MATCH($D$2&"|"&$H$2&"|网点数量",数据底稿1!$Z:$Z,0))="",INDEX(数据底稿1!$R:$R,MATCH($D$2&"|"&$H$2&"|网点数量",数据底稿1!$Z:$Z,0)),INDEX(数据底稿1!$V:$V,MATCH($D$2&"|"&$H$2&"|网点数量",数据底稿1!$Z:$Z,0))))))) -> 90 | G7: 1000 | H7: =IF(ISBLANK(G7),"",F7*E7) -> 3.69 | I7: =INDEX(数据底稿1!$H:$H,MATCH($D$2&"|"&$H$2&"|网点数量",数据底稿1!$Z:$Z,0)) -> 380个 | J7: 单店产出（万元） | K7: =INDEX(数据底稿1!$G:$G,MATCH($D$2&"|"&$H$2&"|单店产出",数据底稿1!$Z:$Z,0)) -> 0.109 | L7: =IF(M7<INDEX(数据底稿1!$I:$I,MATCH($D$2&"|"&$H$2&"|单店产出",数据底稿1!$Z:$Z,0)),INDEX(数据底稿1!$J:$J,MATCH($D$2&"|"&$H$2&"|单店产出",数据底稿1!$Z:$Z,0)),IF(M7<INDEX(数据底稿1!$M:$M,MATCH($D$2&"|"&$H$2&"|单店产出",数据底稿1!$Z:$Z,0)),INDEX(数据底稿1!$N:$N,MATCH($D$2&"|"&$H$2&"|单店产出",数据底稿1!$Z:$Z,0)),IF(INDEX(数据底稿1!$Q:$Q,MATCH($D$2&"|"&$H$2&"|单店产出",数据底稿1!$Z:$Z,0))="",INDEX(数据底稿1!$R:$R,MATCH($D$2&"|"&$H$2&"|单店产出",数据底稿1!$Z:$Z,0)),IF(M7<INDEX(数据底稿1!$Q:$Q,MATCH($D$2&"|"&$H$2&"|单店产出",数据底稿1!$Z:$Z,0)),INDEX(数据底稿1!$R:$R,MATCH($D$2&"|"&$H$2&"|单店产出",数据底稿1!$Z:$Z,0)),IF(INDEX(数据底稿1!$V:$V,MATCH($D$2&"|"&$H$2&"|单店产出",数据底稿1!$Z:$Z,0))="",INDEX(数据底稿1!$R:$R,MATCH($D$2&"|"&$H$2&"|单店产出",数据底稿1!$Z:$Z,0)),INDEX(数据底稿1!$V:$V,MATCH($D$2&"|"&$H$2&"|单店产出",数据底稿1!$Z:$Z,0))))))) -> 90 | M7: 10 | N7: =IF(ISBLANK(M7),"",L7*K7) -> 9.81 | O7: =INDEX(数据底稿1!$H:$H,MATCH($D$2&"|"&$H$2&"|单店产出",数据底稿1!$Z:$Z,0)) -> 4.4万 | Y7: 数据输入
D8: 核心店占比（%） | E8: =INDEX(数据底稿1!$G:$G,MATCH($D$2&"|"&$H$2&"|核心店数量占比",数据底稿1!$Z:$Z,0)) -> 0.041 | F8: =IF(G8<INDEX(数据底稿1!$I:$I,MATCH($D$2&"|"&$H$2&"|核心店数量占比",数据底稿1!$Z:$Z,0)),INDEX(数据底稿1!$J:$J,MATCH($D$2&"|"&$H$2&"|核心店数量占比",数据底稿1!$Z:$Z,0)),IF(G8<INDEX(数据底稿1!$M:$M,MATCH($D$2&"|"&$H$2&"|核心店数量占比",数据底稿1!$Z:$Z,0)),INDEX(数据底稿1!$N:$N,MATCH($D$2&"|"&$H$2&"|核心店数量占比",数据底稿1!$Z:$Z,0)),IF(INDEX(数据底稿1!$Q:$Q,MATCH($D$2&"|"&$H$2&"|核心店数量占比",数据底稿1!$Z:$Z,0))="",INDEX(数据底稿1!$R:$R,MATCH($D$2&"|"&$H$2&"|核心店数量占比",数据底稿1!$Z:$Z,0)),IF(G8<INDEX(数据底稿1!$Q:$Q,MATCH($D$2&"|"&$H$2&"|核心店数量占比",数据底稿1!$Z:$Z,0)),INDEX(数据底稿1!$R:$R,MATCH($D$2&"|"&$H$2&"|核心店数量占比",数据底稿1!$Z:$Z,0)),IF(INDEX(数据底稿1!$V:$V,MATCH($D$2&"|"&$H$2&"|核心店数量占比",数据底稿1!$Z:$Z,0))="",INDEX(数据底稿1!$R:$R,MATCH($D$2&"|"&$H$2&"|核心店数量占比",数据底稿1!$Z:$Z,0)),INDEX(数据底稿1!$V:$V,MATCH($D$2&"|"&$H$2&"|核心店数量占比",数据底稿1!$Z:$Z,0))))))) -> 90 | G8: 0.35 | H8: =IF(ISBLANK(G8),"",F8*E8) -> 3.69 | I8: =IFERROR(TEXT(INDEX(数据底稿1!$H:$H,MATCH($D$2&"|"&$H$2&"|核心店数量占比",数据底稿1!$Z:$Z,0)),"0.0%"),INDEX(数据底稿1!$H:$H,MATCH($D$2&"|"&$H$2&"|核心店数量占比",数据底稿1!$Z:$Z,0))) -> 17.5% | J8: 有效门店占比（%） | K8: =INDEX(数据底稿1!$G:$G,MATCH($D$2&"|"&$H$2&"|有效门店占比",数据底稿1!$Z:$Z,0)) -> 0.09 | L8: =IF(M8<INDEX(数据底稿1!$I:$I,MATCH($D$2&"|"&$H$2&"|有效门店占比",数据底稿1!$Z:$Z,0)),INDEX(数据底稿1!$J:$J,MATCH($D$2&"|"&$H$2&"|有效门店占比",数据底稿1!$Z:$Z,0)),IF(M8<INDEX(数据底稿1!$M:$M,MATCH($D$2&"|"&$H$2&"|有效门店占比",数据底稿1!$Z:$Z,0)),INDEX(数据底稿1!$N:$N,MATCH($D$2&"|"&$H$2&"|有效门店占比",数据底稿1!$Z:$Z,0)),IF(INDEX(数据底稿1!$Q:$Q,MATCH($D$2&"|"&$H$2&"|有效门店占比",数据底稿1!$Z:$Z,0))="",INDEX(数据底稿1!$R:$R,MATCH($D$2&"|"&$H$2&"|有效门店占比",数据底稿1!$Z:$Z,0)),IF(M8<INDEX(数据底稿1!$Q:$Q,MATCH($D$2&"|"&$H$2&"|有效门店占比",数据底稿1!$Z:$Z,0)),INDEX(数据底稿1!$R:$R,MATCH($D$2&"|"&$H$2&"|有效门店占比",数据底稿1!$Z:$Z,0)),IF(INDEX(数据底稿1!$V:$V,MATCH($D$2&"|"&$H$2&"|有效门店占比",数据底稿1!$Z:$Z,0))="",INDEX(数据底稿1!$R:$R,MATCH($D$2&"|"&$H$2&"|有效门店占比",数据底稿1!$Z:$Z,0)),INDEX(数据底稿1!$V:$V,MATCH($D$2&"|"&$H$2&"|有效门店占比",数据底稿1!$Z:$Z,0))))))) -> 90 | M8: 1 | N8: =IF(ISBLANK(M8),"",L8*K8) -> 8.1 | O8: =IFERROR(TEXT(INDEX(数据底稿1!$H:$H,MATCH($D$2&"|"&$H$2&"|有效门店占比",数据底稿1!$Z:$Z,0)),"0.0%"),INDEX(数据底稿1!$H:$H,MATCH($D$2&"|"&$H$2&"|有效门店占比",数据底稿1!$Z:$Z,0))) -> 94.1% | P8: 家装 | Q8: 家装销售占比 | S8: 0.18 | T8: =IF(U8="","",IF(U8>=INDEX(数据底稿2!C7:K7,1,MATCH($D$2&$H$2,数据底稿2!$C$3:$K$3,0)),90,IF(U8>=INDEX(数据底稿2!C8:K8,1,MATCH($D$2&$H$2,数据底稿2!$C$3:$K$3,0)),70,IF(U8>=INDEX(数据底稿2!C9:K9,1,MATCH($D$2&$H$2,数据底稿2!$C$3:$K$3,0)),50,30)))) -> 30 | U8: 0.013 | W8: =IF(U8="","",T8*S8) -> 5.4 | X8: =INDEX(数据底稿2!C7:K7,1,MATCH($D$2&$H$2,数据底稿2!$C$3:$K$3,0)) -> 0.038 | Y8: 城区人口 | Z8: 万人 | AA8: 279
D9: 人均服务网点数（个） | E9: =INDEX(数据底稿1!$G:$G,MATCH($D$2&"|"&$H$2&"|人均服务网点数",数据底稿1!$Z:$Z,0)) -> 0.045 | F9: =IF(G9<INDEX(数据底稿1!$I:$I,MATCH($D$2&"|"&$H$2&"|人均服务网点数",数据底稿1!$Z:$Z,0)),INDEX(数据底稿1!$J:$J,MATCH($D$2&"|"&$H$2&"|人均服务网点数",数据底稿1!$Z:$Z,0)),IF(G9<INDEX(数据底稿1!$M:$M,MATCH($D$2&"|"&$H$2&"|人均服务网点数",数据底稿1!$Z:$Z,0)),INDEX(数据底稿1!$N:$N,MATCH($D$2&"|"&$H$2&"|人均服务网点数",数据底稿1!$Z:$Z,0)),IF(INDEX(数据底稿1!$Q:$Q,MATCH($D$2&"|"&$H$2&"|人均服务网点数",数据底稿1!$Z:$Z,0))="",INDEX(数据底稿1!$R:$R,MATCH($D$2&"|"&$H$2&"|人均服务网点数",数据底稿1!$Z:$Z,0)),IF(G9<INDEX(数据底稿1!$Q:$Q,MATCH($D$2&"|"&$H$2&"|人均服务网点数",数据底稿1!$Z:$Z,0)),INDEX(数据底稿1!$R:$R,MATCH($D$2&"|"&$H$2&"|人均服务网点数",数据底稿1!$Z:$Z,0)),IF(INDEX(数据底稿1!$V:$V,MATCH($D$2&"|"&$H$2&"|人均服务网点数",数据底稿1!$Z:$Z,0))="",INDEX(数据底稿1!$R:$R,MATCH($D$2&"|"&$H$2&"|人均服务网点数",数据底稿1!$Z:$Z,0)),INDEX(数据底稿1!$V:$V,MATCH($D$2&"|"&$H$2&"|人均服务网点数",数据底稿1!$Z:$Z,0))))))) -> 90 | G9: 150 | H9: =IF(ISBLANK(G9),"",F9*E9) -> 4.05 | I9: =IFERROR(TEXT(ROUND(VALUE(SUBSTITUTE(INDEX(数据底稿1!$H:$H,MATCH($D$2&"|"&$H$2&"|人均服务网点数",数据底稿1!$Z:$Z,0)),"个","")),0),"0")&"个",INDEX(数据底稿1!$H:$H,MATCH($D$2&"|"&$H$2&"|人均服务网点数",数据底稿1!$Z:$Z,0))) -> 78个 | J9: 自有人员数量（人） | K9: =INDEX(数据底稿1!$G:$G,MATCH($D$2&"|"&$H$2&"|自有人员数量",数据底稿1!$Z:$Z,0)) -> 0.023 | L9: =IF(M9<INDEX(数据底稿1!$I:$I,MATCH($D$2&"|"&$H$2&"|自有人员数量",数据底稿1!$Z:$Z,0)),INDEX(数据底稿1!$J:$J,MATCH($D$2&"|"&$H$2&"|自有人员数量",数据底稿1!$Z:$Z,0)),IF(M9<INDEX(数据底稿1!$M:$M,MATCH($D$2&"|"&$H$2&"|自有人员数量",数据底稿1!$Z:$Z,0)),INDEX(数据底稿1!$N:$N,MATCH($D$2&"|"&$H$2&"|自有人员数量",数据底稿1!$Z:$Z,0)),IF(INDEX(数据底稿1!$Q:$Q,MATCH($D$2&"|"&$H$2&"|自有人员数量",数据底稿1!$Z:$Z,0))="",INDEX(数据底稿1!$R:$R,MATCH($D$2&"|"&$H$2&"|自有人员数量",数据底稿1!$Z:$Z,0)),IF(M9<INDEX(数据底稿1!$Q:$Q,MATCH($D$2&"|"&$H$2&"|自有人员数量",数据底稿1!$Z:$Z,0)),INDEX(数据底稿1!$R:$R,MATCH($D$2&"|"&$H$2&"|自有人员数量",数据底稿1!$Z:$Z,0)),IF(INDEX(数据底稿1!$V:$V,MATCH($D$2&"|"&$H$2&"|自有人员数量",数据底稿1!$Z:$Z,0))="",INDEX(数据底稿1!$R:$R,MATCH($D$2&"|"&$H$2&"|自有人员数量",数据底稿1!$Z:$Z,0)),INDEX(数据底稿1!$V:$V,MATCH($D$2&"|"&$H$2&"|自有人员数量",数据底稿1!$Z:$Z,0))))))) -> 90 | M9: 6 | N9: =IF(ISBLANK(M9),"",L9*K9) -> 2.07 | O9: =INDEX(数据底稿1!$H:$H,MATCH($D$2&"|"&$H$2&"|自有人员数量",数据底稿1!$Z:$Z,0)) -> 4人
D10: 人效（万元/人） | E10: =INDEX(数据底稿1!$G:$G,MATCH($D$2&"|"&$H$2&"|人效",数据底稿1!$Z:$Z,0)) -> 0.086 | F10: =IF(G10<INDEX(数据底稿1!$I:$I,MATCH($D$2&"|"&$H$2&"|人效",数据底稿1!$Z:$Z,0)),INDEX(数据底稿1!$J:$J,MATCH($D$2&"|"&$H$2&"|人效",数据底稿1!$Z:$Z,0)),IF(G10<INDEX(数据底稿1!$M:$M,MATCH($D$2&"|"&$H$2&"|人效",数据底稿1!$Z:$Z,0)),INDEX(数据底稿1!$N:$N,MATCH($D$2&"|"&$H$2&"|人效",数据底稿1!$Z:$Z,0)),IF(INDEX(数据底稿1!$Q:$Q,MATCH($D$2&"|"&$H$2&"|人效",数据底稿1!$Z:$Z,0))="",INDEX(数据底稿1!$R:$R,MATCH($D$2&"|"&$H$2&"|人效",数据底稿1!$Z:$Z,0)),IF(G10<INDEX(数据底稿1!$Q:$Q,MATCH($D$2&"|"&$H$2&"|人效",数据底稿1!$Z:$Z,0)),INDEX(数据底稿1!$R:$R,MATCH($D$2&"|"&$H$2&"|人效",数据底稿1!$Z:$Z,0)),IF(INDEX(数据底稿1!$V:$V,MATCH($D$2&"|"&$H$2&"|人效",数据底稿1!$Z:$Z,0))="",INDEX(数据底稿1!$R:$R,MATCH($D$2&"|"&$H$2&"|人效",数据底稿1!$Z:$Z,0)),INDEX(数据底稿1!$V:$V,MATCH($D$2&"|"&$H$2&"|人效",数据底稿1!$Z:$Z,0))))))) -> 90 | G10: 1000 | H10: =IF(ISBLANK(G10),"",F10*E10) -> 7.74 | I10: =INDEX(数据底稿1!$H:$H,MATCH($D$2&"|"&$H$2&"|人效",数据底稿1!$Z:$Z,0)) -> 490.9万/人 | J10: 乡镇覆盖率（%） | K10: =INDEX(数据底稿1!$G:$G,MATCH($D$2&"|"&$H$2&"|乡镇覆盖率",数据底稿1!$Z:$Z,0)) -> 0.014 | L10: =IF(M10<INDEX(数据底稿1!$I:$I,MATCH($D$2&"|"&$H$2&"|乡镇覆盖率",数据底稿1!$Z:$Z,0)),INDEX(数据底稿1!$J:$J,MATCH($D$2&"|"&$H$2&"|乡镇覆盖率",数据底稿1!$Z:$Z,0)),IF(M10<INDEX(数据底稿1!$M:$M,MATCH($D$2&"|"&$H$2&"|乡镇覆盖率",数据底稿1!$Z:$Z,0)),INDEX(数据底稿1!$N:$N,MATCH($D$2&"|"&$H$2&"|乡镇覆盖率",数据底稿1!$Z:$Z,0)),IF(INDEX(数据底稿1!$Q:$Q,MATCH($D$2&"|"&$H$2&"|乡镇覆盖率",数据底稿1!$Z:$Z,0))="",INDEX(数据底稿1!$R:$R,MATCH($D$2&"|"&$H$2&"|乡镇覆盖率",数据底稿1!$Z:$Z,0)),IF(M10<INDEX(数据底稿1!$Q:$Q,MATCH($D$2&"|"&$H$2&"|乡镇覆盖率",数据底稿1!$Z:$Z,0)),INDEX(数据底稿1!$R:$R,MATCH($D$2&"|"&$H$2&"|乡镇覆盖率",数据底稿1!$Z:$Z,0)),IF(INDEX(数据底稿1!$V:$V,MATCH($D$2&"|"&$H$2&"|乡镇覆盖率",数据底稿1!$Z:$Z,0))="",INDEX(数据底稿1!$R:$R,MATCH($D$2&"|"&$H$2&"|乡镇覆盖率",数据底稿1!$Z:$Z,0)),INDEX(数据底稿1!$V:$V,MATCH($D$2&"|"&$H$2&"|乡镇覆盖率",数据底稿1!$Z:$Z,0))))))) -> 70 | M10: 1 | N10: =IF(ISBLANK(M10),"",L10*K10) -> 0.98 | O10: =IFERROR(TEXT(INDEX(数据底稿1!$H:$H,MATCH($D$2&"|"&$H$2&"|乡镇覆盖率",数据底稿1!$Z:$Z,0)),"0.0%"),INDEX(数据底稿1!$H:$H,MATCH($D$2&"|"&$H$2&"|乡镇覆盖率",数据底稿1!$Z:$Z,0))) -> 100.0% | Q10: 家装公司产出/月（元） | S10: 0.17 | T10: =IF(U10="","",IF(U10>=INDEX(数据底稿2!C10:K10,1,MATCH($D$2&$H$2,数据底稿2!$C$3:$K$3,0)),90,IF(U10>=INDEX(数据底稿2!C11:K11,1,MATCH($D$2&$H$2,数据底稿2!$C$3:$K$3,0)),70,IF(U10>=INDEX(数据底稿2!C12:K12,1,MATCH($D$2&$H$2,数据底稿2!$C$3:$K$3,0)),50,30)))) -> 70 | U10: 2000 | W10: =IF(U10="","",T10*S10) -> 11.9 | X10: =INDEX(数据底稿2!C10:K10,1,MATCH($D$2&$H$2,数据底稿2!$C$3:$K$3,0)) -> 2864 | Y10: 户均居住面积 | Z10: m²/户 | AA10: 90
C11: 零售 | D11: 会员数量（人） | E11: =INDEX(数据底稿1!$G:$G,MATCH($D$2&"|"&$H$2&"|会员数量",数据底稿1!$Z:$Z,0)) -> 0.025 | F11: =IF(G11<INDEX(数据底稿1!$I:$I,MATCH($D$2&"|"&$H$2&"|会员数量",数据底稿1!$Z:$Z,0)),INDEX(数据底稿1!$J:$J,MATCH($D$2&"|"&$H$2&"|会员数量",数据底稿1!$Z:$Z,0)),IF(G11<INDEX(数据底稿1!$M:$M,MATCH($D$2&"|"&$H$2&"|会员数量",数据底稿1!$Z:$Z,0)),INDEX(数据底稿1!$N:$N,MATCH($D$2&"|"&$H$2&"|会员数量",数据底稿1!$Z:$Z,0)),IF(INDEX(数据底稿1!$Q:$Q,MATCH($D$2&"|"&$H$2&"|会员数量",数据底稿1!$Z:$Z,0))="",INDEX(数据底稿1!$R:$R,MATCH($D$2&"|"&$H$2&"|会员数量",数据底稿1!$Z:$Z,0)),IF(G11<INDEX(数据底稿1!$Q:$Q,MATCH($D$2&"|"&$H$2&"|会员数量",数据底稿1!$Z:$Z,0)),INDEX(数据底稿1!$R:$R,MATCH($D$2&"|"&$H$2&"|会员数量",数据底稿1!$Z:$Z,0)),IF(INDEX(数据底稿1!$V:$V,MATCH($D$2&"|"&$H$2&"|会员数量",数据底稿1!$Z:$Z,0))="",INDEX(数据底稿1!$R:$R,MATCH($D$2&"|"&$H$2&"|会员数量",数据底稿1!$Z:$Z,0)),INDEX(数据底稿1!$V:$V,MATCH($D$2&"|"&$H$2&"|会员数量",数据底稿1!$Z:$Z,0))))))) -> 90 | G11: 200 | H11: =IF(ISBLANK(G11),"",F11*E11) -> 2.25 | I11: =INDEX(数据底稿1!$H:$H,MATCH($D$2&"|"&$H$2&"|会员数量",数据底稿1!$Z:$Z,0)) -> 127人 | J11: 会员人均产出（万元/人） | K11: =INDEX(数据底稿1!$G:$G,MATCH($D$2&"|"&$H$2&"|会员人均产出",数据底稿1!$Z:$Z,0)) -> 0.025 | L11: =IF(M11<INDEX(数据底稿1!$I:$I,MATCH($D$2&"|"&$H$2&"|会员人均产出",数据底稿1!$Z:$Z,0)),INDEX(数据底稿1!$J:$J,MATCH($D$2&"|"&$H$2&"|会员人均产出",数据底稿1!$Z:$Z,0)),IF(M11<INDEX(数据底稿1!$M:$M,MATCH($D$2&"|"&$H$2&"|会员人均产出",数据底稿1!$Z:$Z,0)),INDEX(数据底稿1!$N:$N,MATCH($D$2&"|"&$H$2&"|会员人均产出",数据底稿1!$Z:$Z,0)),IF(INDEX(数据底稿1!$Q:$Q,MATCH($D$2&"|"&$H$2&"|会员人均产出",数据底稿1!$Z:$Z,0))="",INDEX(数据底稿1!$R:$R,MATCH($D$2&"|"&$H$2&"|会员人均产出",数据底稿1!$Z:$Z,0)),IF(M11<INDEX(数据底稿1!$Q:$Q,MATCH($D$2&"|"&$H$2&"|会员人均产出",数据底稿1!$Z:$Z,0)),INDEX(数据底稿1!$R:$R,MATCH($D$2&"|"&$H$2&"|会员人均产出",数据底稿1!$Z:$Z,0)),IF(INDEX(数据底稿1!$V:$V,MATCH($D$2&"|"&$H$2&"|会员人均产出",数据底稿1!$Z:$Z,0))="",INDEX(数据底稿1!$R:$R,MATCH($D$2&"|"&$H$2&"|会员人均产出",数据底稿1!$Z:$Z,0)),INDEX(数据底稿1!$V:$V,MATCH($D$2&"|"&$H$2&"|会员人均产出",数据底稿1!$Z:$Z,0))))))) -> 90 | M11: 2 | N11: =IF(ISBLANK(M11),"",L11*K11) -> 2.25 | O11: =IFERROR(TEXT(VALUE(SUBSTITUTE(SUBSTITUTE(INDEX(数据底稿1!$H:$H,MATCH($D$2&"|"&$H$2&"|会员人均产出",数据底稿1!$Z:$Z,0)),"万/人",""),"万","")),"0.00")&"万/人",INDEX(数据底稿1!$H:$H,MATCH($D$2&"|"&$H$2&"|会员人均产出",数据底稿1!$Z:$Z,0))) -> 1.01万/人
C12: 渠道均衡发展 | D12: 渠道数量 | E12: =INDEX(数据底稿1!$G:$G,MATCH($D$2&"|"&$H$2&"|渠道数量",数据底稿1!$Z:$Z,0)) -> 0.06 | F12: =IF(G12<INDEX(数据底稿1!$I:$I,MATCH($D$2&"|"&$H$2&"|渠道数量",数据底稿1!$Z:$Z,0)),INDEX(数据底稿1!$J:$J,MATCH($D$2&"|"&$H$2&"|渠道数量",数据底稿1!$Z:$Z,0)),IF(G12<INDEX(数据底稿1!$M:$M,MATCH($D$2&"|"&$H$2&"|渠道数量",数据底稿1!$Z:$Z,0)),INDEX(数据底稿1!$N:$N,MATCH($D$2&"|"&$H$2&"|渠道数量",数据底稿1!$Z:$Z,0)),IF(OR(INDEX(数据底稿1!$Q:$Q,MATCH($D$2&"|"&$H$2&"|渠道数量",数据底稿1!$Z:$Z,0))="",G12<INDEX(数据底稿1!$Q:$Q,MATCH($D$2&"|"&$H$2&"|渠道数量",数据底稿1!$Z:$Z,0))),INDEX(数据底稿1!$R:$R,MATCH($D$2&"|"&$H$2&"|渠道数量",数据底稿1!$Z:$Z,0)),INDEX(数据底稿1!$V:$V,MATCH($D$2&"|"&$H$2&"|渠道数量",数据底稿1!$Z:$Z,0))))) -> 90 | G12: 4 | H12: =IF(ISBLANK(G12),"",F12*E12) -> 5.4 | I12: =INDEX(数据底稿1!$H:$H,MATCH($D$2&"|"&$H$2&"|渠道数量",数据底稿1!$Z:$Z,0)) -> 4个 | Y12: 户均人口 | Z12: 人/户 | AA12: 2.6
B13: 品类维度 | C13: 品类均衡发展 | D13: 品类数量 | E13: =INDEX(数据底稿1!$G:$G,MATCH($D$2&"|"&$H$2&"|品类数量",数据底稿1!$Z:$Z,0)) -> 0.06 | F13: =IF(G13<INDEX(数据底稿1!$I:$I,MATCH($D$2&"|"&$H$2&"|品类数量",数据底稿1!$Z:$Z,0)),INDEX(数据底稿1!$J:$J,MATCH($D$2&"|"&$H$2&"|品类数量",数据底稿1!$Z:$Z,0)),IF(G13<INDEX(数据底稿1!$M:$M,MATCH($D$2&"|"&$H$2&"|品类数量",数据底稿1!$Z:$Z,0)),INDEX(数据底稿1!$N:$N,MATCH($D$2&"|"&$H$2&"|品类数量",数据底稿1!$Z:$Z,0)),IF(OR(INDEX(数据底稿1!$Q:$Q,MATCH($D$2&"|"&$H$2&"|品类数量",数据底稿1!$Z:$Z,0))="",G13<INDEX(数据底稿1!$Q:$Q,MATCH($D$2&"|"&$H$2&"|品类数量",数据底稿1!$Z:$Z,0))),INDEX(数据底稿1!$R:$R,MATCH($D$2&"|"&$H$2&"|品类数量",数据底稿1!$Z:$Z,0)),INDEX(数据底稿1!$V:$V,MATCH($D$2&"|"&$H$2&"|品类数量",数据底稿1!$Z:$Z,0))))) -> 90 | G13: 5 | H13: =IF(ISBLANK(G13),"",F13*E13) -> 5.4 | I13: =INDEX(数据底稿1!$H:$H,MATCH($D$2&"|"&$H$2&"|品类数量",数据底稿1!$Z:$Z,0)) -> 5个 | P13: 服务 | Q13: 工单转化率 | S13: 0.24 | T13: =IF(U13="","",IF(U13>=INDEX(数据底稿2!C16:K16,1,MATCH($D$2&$H$2,数据底稿2!$C$3:$K$3,0)),90,IF(U13>=INDEX(数据底稿2!C17:K17,1,MATCH($D$2&$H$2,数据底稿2!$C$3:$K$3,0)),70,IF(U13>=INDEX(数据底稿2!C18:K18,1,MATCH($D$2&$H$2,数据底稿2!$C$3:$K$3,0)),50,30)))) -> 90 | U13: 0.28 | W13: =IF(U13="","",T13*S13) -> 21.6 | X13: =INDEX(数据底稿2!C16:K16,1,MATCH($D$2&$H$2,数据底稿2!$C$3:$K$3,0)) -> 0.274 | Y13: =IF(AA6="总体","雨虹产品总体单价",AA6&"品类单价") -> 防水品类单价 | Z13: 元/m² | AA13: 30
A14: 支撑层 | B14: 公司维度 | C14: 会议场次 | D14: 分销会次数（次） | E14: =INDEX(数据底稿1!$G:$G,MATCH($D$2&"|"&$H$2&"|分销会次数",数据底稿1!$Z:$Z,0)) -> 0.03 | F14: =IF(G14<INDEX(数据底稿1!$I:$I,MATCH($D$2&"|"&$H$2&"|分销会次数",数据底稿1!$Z:$Z,0)),INDEX(数据底稿1!$J:$J,MATCH($D$2&"|"&$H$2&"|分销会次数",数据底稿1!$Z:$Z,0)),IF(G14<INDEX(数据底稿1!$M:$M,MATCH($D$2&"|"&$H$2&"|分销会次数",数据底稿1!$Z:$Z,0)),INDEX(数据底稿1!$N:$N,MATCH($D$2&"|"&$H$2&"|分销会次数",数据底稿1!$Z:$Z,0)),IF(INDEX(数据底稿1!$Q:$Q,MATCH($D$2&"|"&$H$2&"|分销会次数",数据底稿1!$Z:$Z,0))="",INDEX(数据底稿1!$R:$R,MATCH($D$2&"|"&$H$2&"|分销会次数",数据底稿1!$Z:$Z,0)),IF(G14<INDEX(数据底稿1!$Q:$Q,MATCH($D$2&"|"&$H$2&"|分销会次数",数据底稿1!$Z:$Z,0)),INDEX(数据底稿1!$R:$R,MATCH($D$2&"|"&$H$2&"|分销会次数",数据底稿1!$Z:$Z,0)),IF(INDEX(数据底稿1!$V:$V,MATCH($D$2&"|"&$H$2&"|分销会次数",数据底稿1!$Z:$Z,0))="",INDEX(数据底稿1!$R:$R,MATCH($D$2&"|"&$H$2&"|分销会次数",数据底稿1!$Z:$Z,0)),INDEX(数据底稿1!$V:$V,MATCH($D$2&"|"&$H$2&"|分销会次数",数据底稿1!$Z:$Z,0))))))) -> 90 | G14: 8 | H14: =IF(ISBLANK(G14),"",F14*E14) -> 2.7 | I14: =INDEX(数据底稿1!$H:$H,MATCH($D$2&"|"&$H$2&"|分销会次数",数据底稿1!$Z:$Z,0)) -> 5次 | J14: 专业人士会议次数（次） | K14: =INDEX(数据底稿1!$G:$G,MATCH($D$2&"|"&$H$2&"|专业人士会议次数",数据底稿1!$Z:$Z,0)) -> 0.029 | L14: =IF(M14<INDEX(数据底稿1!$I:$I,MATCH($D$2&"|"&$H$2&"|专业人士会议次数",数据底稿1!$Z:$Z,0)),INDEX(数据底稿1!$J:$J,MATCH($D$2&"|"&$H$2&"|专业人士会议次数",数据底稿1!$Z:$Z,0)),IF(M14<INDEX(数据底稿1!$M:$M,MATCH($D$2&"|"&$H$2&"|专业人士会议次数",数据底稿1!$Z:$Z,0)),INDEX(数据底稿1!$N:$N,MATCH($D$2&"|"&$H$2&"|专业人士会议次数",数据底稿1!$Z:$Z,0)),IF(M14<INDEX(数据底稿1!$Q:$Q,MATCH($D$2&"|"&$H$2&"|专业人士会议次数",数据底稿1!$Z:$Z,0)),INDEX(数据底稿1!$R:$R,MATCH($D$2&"|"&$H$2&"|专业人士会议次数",数据底稿1!$Z:$Z,0)),IF(M14<=40,INDEX(数据底稿1!$V:$V,MATCH($D$2&"|"&$H$2&"|专业人士会议次数",数据底稿1!$Z:$Z,0)),50)))) -> 90 | M14: 38 | N14: =IF(ISBLANK(M14),"",L14*K14) -> 2.61 | O14: =INDEX(数据底稿1!$H:$H,MATCH($D$2&"|"&$H$2&"|专业人士会议次数",数据底稿1!$Z:$Z,0)) -> 28次 | Y14: ="品类单价填写提示：建议根据所在区域实际情况，结合该品类适用的房屋面积比重，综合测算品类单价后填写。"&IF(AA6="总体","总体单价为所有品类单价的加总。","") -> 品类单价填写提示：建议根据所在区域实际情况，结合该品类适用的房屋面积比重，综合测算品类单价后填写。
C15: 仓储效率 | D15: 坪效（万元/平方米） | E15: =INDEX(数据底稿1!$G:$G,MATCH($D$2&"|"&$H$2&"|坪效",数据底稿1!$Z:$Z,0)) -> 0.039 | F15: =IF(G15<INDEX(数据底稿1!$I:$I,MATCH($D$2&"|"&$H$2&"|坪效",数据底稿1!$Z:$Z,0)),INDEX(数据底稿1!$J:$J,MATCH($D$2&"|"&$H$2&"|坪效",数据底稿1!$Z:$Z,0)),IF(G15<INDEX(数据底稿1!$M:$M,MATCH($D$2&"|"&$H$2&"|坪效",数据底稿1!$Z:$Z,0)),INDEX(数据底稿1!$N:$N,MATCH($D$2&"|"&$H$2&"|坪效",数据底稿1!$Z:$Z,0)),IF(INDEX(数据底稿1!$Q:$Q,MATCH($D$2&"|"&$H$2&"|坪效",数据底稿1!$Z:$Z,0))="",INDEX(数据底稿1!$R:$R,MATCH($D$2&"|"&$H$2&"|坪效",数据底稿1!$Z:$Z,0)),IF(G15<INDEX(数据底稿1!$Q:$Q,MATCH($D$2&"|"&$H$2&"|坪效",数据底稿1!$Z:$Z,0)),INDEX(数据底稿1!$R:$R,MATCH($D$2&"|"&$H$2&"|坪效",数据底稿1!$Z:$Z,0)),IF(INDEX(数据底稿1!$V:$V,MATCH($D$2&"|"&$H$2&"|坪效",数据底稿1!$Z:$Z,0))="",INDEX(数据底稿1!$R:$R,MATCH($D$2&"|"&$H$2&"|坪效",数据底稿1!$Z:$Z,0)),INDEX(数据底稿1!$V:$V,MATCH($D$2&"|"&$H$2&"|坪效",数据底稿1!$Z:$Z,0))))))) -> 90 | G15: 3 | H15: =IF(ISBLANK(G15),"",F15*E15) -> 3.51 | I15: =IFERROR(TEXT(VALUE(SUBSTITUTE(INDEX(数据底稿1!$H:$H,MATCH($D$2&"|"&$H$2&"|坪效",数据底稿1!$Z:$Z,0)),"万/平方米","")),"0.00")&"万/平方米",INDEX(数据底稿1!$H:$H,MATCH($D$2&"|"&$H$2&"|坪效",数据底稿1!$Z:$Z,0))) -> 1.38万/平方米 | Q15: 月均工单数量（单） | S15: 0.16 | T15: =IF(U15="","",IF(U15>=INDEX(数据底稿2!C13:K13,1,MATCH($D$2&$H$2,数据底稿2!$C$3:$K$3,0)),90,IF(U15>=INDEX(数据底稿2!C14:K14,1,MATCH($D$2&$H$2,数据底稿2!$C$3:$K$3,0)),70,IF(U15>=INDEX(数据底稿2!C15:K15,1,MATCH($D$2&$H$2,数据底稿2!$C$3:$K$3,0)),50,30)))) -> 70 | U15: 20 | W15: =IF(U15="","",T15*S15) -> 11.2 | X15: =INDEX(数据底稿2!C13:K13,1,MATCH($D$2&$H$2,数据底稿2!$C$3:$K$3,0)) -> 38
C16: 数字化水平 （a/b/c/d） | E16: =INDEX(数据底稿1!$G:$G,MATCH($D$2&"|"&$H$2&"|数字化水平",数据底稿1!$Z:$Z,0)) -> 0.033 | F16: =IF(G16=INDEX(数据底稿1!$I:$I,MATCH($D$2&"|"&$H$2&"|数字化水平",数据底稿1!$Z:$Z,0)),INDEX(数据底稿1!$J:$J,MATCH($D$2&"|"&$H$2&"|数字化水平",数据底稿1!$Z:$Z,0)),IF(G16=INDEX(数据底稿1!$M:$M,MATCH($D$2&"|"&$H$2&"|数字化水平",数据底稿1!$Z:$Z,0)),INDEX(数据底稿1!$N:$N,MATCH($D$2&"|"&$H$2&"|数字化水平",数据底稿1!$Z:$Z,0)),IF(G16=INDEX(数据底稿1!$Q:$Q,MATCH($D$2&"|"&$H$2&"|数字化水平",数据底稿1!$Z:$Z,0)),INDEX(数据底稿1!$R:$R,MATCH($D$2&"|"&$H$2&"|数字化水平",数据底稿1!$Z:$Z,0)),IF(G16=INDEX(数据底稿1!$U:$U,MATCH($D$2&"|"&$H$2&"|数字化水平",数据底稿1!$Z:$Z,0)),INDEX(数据底稿1!$V:$V,MATCH($D$2&"|"&$H$2&"|数字化水平",数据底稿1!$Z:$Z,0)),0)))) -> 90 | G16: c | H16: =IF(ISBLANK(G16),"",F16*E16) -> 2.97 | I16: a. 仅拥有进销存数字化系统水平 b. 能够进行数据分析水平 c. 具有数字化指标洞察水平 d. 尚未采用数字化系统 | Y16: 雨虹实际销售额 | Z16: 万元 | AA16: 3000.1
A18: 意愿层 | B18: 意愿维度 | C18: 活动参与度 （a/b/c） | E18: =INDEX(数据底稿1!$G:$G,MATCH($D$2&"|"&$H$2&"|活动参与度",数据底稿1!$Z:$Z,0)) -> 0.015 | F18: =IF(G18=INDEX(数据底稿1!$I:$I,MATCH($D$2&"|"&$H$2&"|活动参与度",数据底稿1!$Z:$Z,0)),INDEX(数据底稿1!$J:$J,MATCH($D$2&"|"&$H$2&"|活动参与度",数据底稿1!$Z:$Z,0)),IF(G18=INDEX(数据底稿1!$M:$M,MATCH($D$2&"|"&$H$2&"|活动参与度",数据底稿1!$Z:$Z,0)),INDEX(数据底稿1!$N:$N,MATCH($D$2&"|"&$H$2&"|活动参与度",数据底稿1!$Z:$Z,0)),IF(G18=INDEX(数据底稿1!$Q:$Q,MATCH($D$2&"|"&$H$2&"|活动参与度",数据底稿1!$Z:$Z,0)),INDEX(数据底稿1!$R:$R,MATCH($D$2&"|"&$H$2&"|活动参与度",数据底稿1!$Z:$Z,0)),IF(G18=INDEX(数据底稿1!$U:$U,MATCH($D$2&"|"&$H$2&"|活动参与度",数据底稿1!$Z:$Z,0)),INDEX(数据底稿1!$V:$V,MATCH($D$2&"|"&$H$2&"|活动参与度",数据底稿1!$Z:$Z,0)),0)))) -> 90 | G18: a | H18: =IF(ISBLANK(G18),"",F18*E18) -> 1.35 | I18: a. 积极参与品牌方（YH）日常会议、培训、活动，并表现突出 b. 参与品牌方（YH）日常会议、培训、活动，较少存在请假、早退等情况 c. 基本不参与品牌方（YH）日常会议、培训、活动 | P18: 品类及渠道参考值 | Y18: 计算输出
Q19: 防水 | R19: 砂浆 | U19: 美缝 | W19: 卷材 | Y19: ="市场容量（"&AA6&"品类）" -> 市场容量（防水品类） | Z19: 万元 | AA19: =AA8/AA12*AA10*AA13*5% -> 14486.538
C20: 经营意愿 （a/b/c） | E20: =INDEX(数据底稿1!$G:$G,MATCH($D$2&"|"&$H$2&"|经营意愿",数据底稿1!$Z:$Z,0)) -> 0.02 | F20: =IF(G20=INDEX(数据底稿1!$I:$I,MATCH($D$2&"|"&$H$2&"|经营意愿",数据底稿1!$Z:$Z,0)),INDEX(数据底稿1!$J:$J,MATCH($D$2&"|"&$H$2&"|经营意愿",数据底稿1!$Z:$Z,0)),IF(G20=INDEX(数据底稿1!$M:$M,MATCH($D$2&"|"&$H$2&"|经营意愿",数据底稿1!$Z:$Z,0)),INDEX(数据底稿1!$N:$N,MATCH($D$2&"|"&$H$2&"|经营意愿",数据底稿1!$Z:$Z,0)),IF(G20=INDEX(数据底稿1!$Q:$Q,MATCH($D$2&"|"&$H$2&"|经营意愿",数据底稿1!$Z:$Z,0)),INDEX(数据底稿1!$R:$R,MATCH($D$2&"|"&$H$2&"|经营意愿",数据底稿1!$Z:$Z,0)),IF(G20=INDEX(数据底稿1!$U:$U,MATCH($D$2&"|"&$H$2&"|经营意愿",数据底稿1!$Z:$Z,0)),INDEX(数据底稿1!$V:$V,MATCH($D$2&"|"&$H$2&"|经营意愿",数据底稿1!$Z:$Z,0)),0)))) -> 90 | G20: a | H20: =IF(ISBLANK(G20),"",F20*E20) -> 1.8 | I20: a. 对于YH品牌存在巨大经营信心，积极与品牌方（YH）互动沟通，每周不少于1次同品牌方（YH）开展经营沟通，愿意配合品牌方（YH）积极开展市场活动，并投入人力物力等资源开展经营 b. 对于YH品牌存在经营信心，较为配合执行品牌方（YH）市场活动政策 c. 计划放弃经营YH品牌（指经销商解约），不配合品牌方（YH）日常管理，不协助品牌方（YH）执行市场活动政策
P21: 优秀值 | Q21: =IFERROR(INDEX(数据底稿2!$A$50:$N$59,MATCH($D$2&$H$2,数据底稿2!$A$50:$A$59,0),2),"/") -> 458.8万 | R21: =IFERROR(INDEX(数据底稿2!$A$50:$N$59,MATCH($D$2&$H$2,数据底稿2!$A$50:$A$59,0),3),"/") -> 754.2万 | U21: =IFERROR(INDEX(数据底稿2!$A$50:$N$59,MATCH($D$2&$H$2,数据底稿2!$A$50:$A$59,0),4),"/") -> 112.7万 | W21: =IFERROR(INDEX(数据底稿2!$A$50:$N$59,MATCH($D$2&$H$2,数据底稿2!$A$50:$A$59,0),5),"/") -> 189.2万 | Y21: ="市场份额（"&AA6&"品类）" -> 市场份额（防水品类） | Z21: / | AA21: =IF(AA19=0,"-",AA16/AA19) -> 0.20709571
C22: 文化认知度 （a/b/c） | E22: =INDEX(数据底稿1!$G:$G,MATCH($D$2&"|"&$H$2&"|文化认知度",数据底稿1!$Z:$Z,0)) -> 0.015 | F22: =IF(G22=INDEX(数据底稿1!$I:$I,MATCH($D$2&"|"&$H$2&"|文化认知度",数据底稿1!$Z:$Z,0)),INDEX(数据底稿1!$J:$J,MATCH($D$2&"|"&$H$2&"|文化认知度",数据底稿1!$Z:$Z,0)),IF(G22=INDEX(数据底稿1!$M:$M,MATCH($D$2&"|"&$H$2&"|文化认知度",数据底稿1!$Z:$Z,0)),INDEX(数据底稿1!$N:$N,MATCH($D$2&"|"&$H$2&"|文化认知度",数据底稿1!$Z:$Z,0)),IF(G22=INDEX(数据底稿1!$Q:$Q,MATCH($D$2&"|"&$H$2&"|文化认知度",数据底稿1!$Z:$Z,0)),INDEX(数据底稿1!$R:$R,MATCH($D$2&"|"&$H$2&"|文化认知度",数据底稿1!$Z:$Z,0)),IF(G22=INDEX(数据底稿1!$U:$U,MATCH($D$2&"|"&$H$2&"|文化认知度",数据底稿1!$Z:$Z,0)),INDEX(数据底稿1!$V:$V,MATCH($D$2&"|"&$H$2&"|文化认知度",数据底稿1!$Z:$Z,0)),0)))) -> 90 | G22: a | H22: =IF(ISBLANK(G22),"",F22*E22) -> 1.35 | I22: a. 对于东方雨虹企业文化存在清晰认知，认同东方雨虹企业文化，并在日常市场经营活动中积极践行 b. 清楚了解东方雨虹企业文化，对于东方雨虹企业文化存在认同 c. 不清楚东方雨虹企业文化，不认同东方雨虹企业文化 | Y22: 公式：市场容量 = 人口(万) ÷ 户均人口 × 户均居住面积(m²) × 品类单价(元/m²) × 5%。 市场份额 = 雨虹实际销售额 ÷ 市场容量。注：5%系数按房屋20年翻新一次估算。
Q23: 墙辅 | R23: 胶业 | U23: 管业 | Y23: 2. 区域市场竞争格局诊断
A24: 最终得分 | C24: =SUM(H6:H23,N6:N11,N14)*数据底稿3!B3+SUM(W6,W8,W10,W13,W15)*数据底稿3!B4 -> 90.416
P25: 优秀值 | Q25: =IFERROR(INDEX(数据底稿2!$A$50:$N$59,MATCH($D$2&$H$2,数据底稿2!$A$50:$A$59,0),6),"/") -> 52.7万 | R25: =IFERROR(INDEX(数据底稿2!$A$50:$N$59,MATCH($D$2&$H$2,数据底稿2!$A$50:$A$59,0),7),"/") -> 20.2万 | U25: =IFERROR(INDEX(数据底稿2!$A$50:$N$59,MATCH($D$2&$H$2,数据底稿2!$A$50:$A$59,0),8),"/") -> 21.3万 | Y25: 数据输入
A26: 评语 | C26: 结果性评价 | D26: 合同达成率 | G26: =IF(OR(G6="",ISERROR(G6)),"",IFERROR(IF(G6<=INDEX(数据底稿1!$I:$I,MATCH($D$2&"|"&$H$2&"|合同达成率",数据底稿1!$Z:$Z,0)),INDEX(数据底稿1!$L:$L,MATCH($D$2&"|"&$H$2&"|合同达成率",数据底稿1!$Z:$Z,0)),IF(G6<=INDEX(数据底稿1!$M:$M,MATCH($D$2&"|"&$H$2&"|合同达成率",数据底稿1!$Z:$Z,0)),INDEX(数据底稿1!$P:$P,MATCH($D$2&"|"&$H$2&"|合同达成率",数据底稿1!$Z:$Z,0)),IF(OR(INDEX(数据底稿1!$Q:$Q,MATCH($D$2&"|"&$H$2&"|合同达成率",数据底稿1!$Z:$Z,0))="",G6<=INDEX(数据底稿1!$Q:$Q,MATCH($D$2&"|"&$H$2&"|合同达成率",数据底稿1!$Z:$Z,0))),INDEX(数据底稿1!$T:$T,MATCH($D$2&"|"&$H$2&"|合同达成率",数据底稿1!$Z:$Z,0)),IFERROR(IF(INDEX(数据底稿1!$X:$X,MATCH($D$2&"|"&$H$2&"|合同达成率",数据底稿1!$Z:$Z,0))="","",INDEX(数据底稿1!$X:$X,MATCH($D$2&"|"&$H$2&"|合同达成率",数据底稿1!$Z:$Z,0))),"")))),"")) -> 全年合同达百，整体表现优异。建议深入分析单份合同达成差异，防范个别合同达成不力带来的风险。 | Y26: 品牌 | AA26: 年度预估销售(万元)
D27: 销售增长率 | G27: =IF(OR(M6="",ISERROR(M6)),"",IFERROR(IF(M6<=INDEX(数据底稿1!$I:$I,MATCH($D$2&"|"&$H$2&"|销售增长率",数据底稿1!$Z:$Z,0)),INDEX(数据底稿1!$L:$L,MATCH($D$2&"|"&$H$2&"|销售增长率",数据底稿1!$Z:$Z,0)),IF(M6<=INDEX(数据底稿1!$M:$M,MATCH($D$2&"|"&$H$2&"|销售增长率",数据底稿1!$Z:$Z,0)),INDEX(数据底稿1!$P:$P,MATCH($D$2&"|"&$H$2&"|销售增长率",数据底稿1!$Z:$Z,0)),IF(OR(INDEX(数据底稿1!$Q:$Q,MATCH($D$2&"|"&$H$2&"|销售增长率",数据底稿1!$Z:$Z,0))="",M6<=INDEX(数据底稿1!$Q:$Q,MATCH($D$2&"|"&$H$2&"|销售增长率",数据底稿1!$Z:$Z,0))),INDEX(数据底稿1!$T:$T,MATCH($D$2&"|"&$H$2&"|销售增长率",数据底稿1!$Z:$Z,0)),IFERROR(IF(INDEX(数据底稿1!$X:$X,MATCH($D$2&"|"&$H$2&"|销售增长率",数据底稿1!$Z:$Z,0))="","",INDEX(数据底稿1!$X:$X,MATCH($D$2&"|"&$H$2&"|销售增长率",数据底稿1!$Z:$Z,0))),"")))),"")) -> 销售增长率处于同类经销商中的领先水平，增长动力强劲。建议关注各品类的增长表现，识别增长引擎品类，制定可持续增长策略，避免短期波动影响长期发展。 | Q27: 分销 | R27: 零售 | U27: 家装 | W27: 服务 | Y27: 雨虹 | AA27: 100
C28: 渠道维度 | D28: 网点数量 | G28: =IF(OR(C26=FALSE,C26="",ISERROR(C26)),"",IF(OR(G7="",ISERROR(G7)),"",IFERROR(IF(G7<=INDEX(数据底稿1!$I:$I,MATCH($D$2&"|"&$H$2&"|网点数量",数据底稿1!$Z:$Z,0)),INDEX(数据底稿1!$L:$L,MATCH($D$2&"|"&$H$2&"|网点数量",数据底稿1!$Z:$Z,0)),IF(G7<=INDEX(数据底稿1!$M:$M,MATCH($D$2&"|"&$H$2&"|网点数量",数据底稿1!$Z:$Z,0)),INDEX(数据底稿1!$P:$P,MATCH($D$2&"|"&$H$2&"|网点数量",数据底稿1!$Z:$Z,0)),IF(OR(INDEX(数据底稿1!$Q:$Q,MATCH($D$2&"|"&$H$2&"|网点数量",数据底稿1!$Z:$Z,0))="",G7<=INDEX(数据底稿1!$Q:$Q,MATCH($D$2&"|"&$H$2&"|网点数量",数据底稿1!$Z:$Z,0))),INDEX(数据底稿1!$T:$T,MATCH($D$2&"|"&$H$2&"|网点数量",数据底稿1!$Z:$Z,0)),IFERROR(IF(INDEX(数据底稿1!$X:$X,MATCH($D$2&"|"&$H$2&"|网点数量",数据底稿1!$Z:$Z,0))="","",INDEX(数据底稿1!$X:$X,MATCH($D$2&"|"&$H$2&"|网点数量",数据底稿1!$Z:$Z,0))),"")))),""))) -> 网点数量处于同类经销商中的领先水平，网点覆盖广泛，网络基础扎实。建议重点提升单店产值和核心店占比，优化网点质量；同时建立网点分级管理体系，提高网点运营效率。 | Y28: 德高 | AA28: 80
D29: 核心店数量占比 | G29: =IF(OR(C26=FALSE,C26="",ISERROR(C26)),"",IF(OR(G8="",ISERROR(G8)),"",IFERROR(IF(G8<=INDEX(数据底稿1!$I:$I,MATCH($D$2&"|"&$H$2&"|核心店数量占比",数据底稿1!$Z:$Z,0)),INDEX(数据底稿1!$L:$L,MATCH($D$2&"|"&$H$2&"|核心店数量占比",数据底稿1!$Z:$Z,0)),IF(G8<=INDEX(数据底稿1!$M:$M,MATCH($D$2&"|"&$H$2&"|核心店数量占比",数据底稿1!$Z:$Z,0)),INDEX(数据底稿1!$P:$P,MATCH($D$2&"|"&$H$2&"|核心店数量占比",数据底稿1!$Z:$Z,0)),IF(OR(INDEX(数据底稿1!$Q:$Q,MATCH($D$2&"|"&$H$2&"|核心店数量占比",数据底稿1!$Z:$Z,0))="",G8<=INDEX(数据底稿1!$Q:$Q,MATCH($D$2&"|"&$H$2&"|核心店数量占比",数据底稿1!$Z:$Z,0))),INDEX(数据底稿1!$T:$T,MATCH($D$2&"|"&$H$2&"|核心店数量占比",数据底稿1!$Z:$Z,0)),IFERROR(IF(INDEX(数据底稿1!$X:$X,MATCH($D$2&"|"&$H$2&"|核心店数量占比",数据底稿1!$Z:$Z,0))="","",INDEX(数据底稿1!$X:$X,MATCH($D$2&"|"&$H$2&"|核心店数量占比",数据底稿1!$Z:$Z,0))),"")))),""))) -> 核心店数量占比处于同类经销商中的领先水平，核心资源集中，分销渠道增长由核心店驱动，市场竞争力强。建议持续关注核心店达成情况，保持增长动力。 | P29: 优秀值 | Q29: =IFERROR(INDEX(数据底稿2!$A$50:$N$59,MATCH($D$2&$H$2,数据底稿2!$A$50:$A$59,0),9),"/") -> 1250.5万 | R29: =IFERROR(INDEX(数据底稿2!$A$50:$N$59,MATCH($D$2&$H$2,数据底稿2!$A$50:$A$59,0),10),"/") -> 71.3万 | U29: =IFERROR(INDEX(数据底稿2!$A$50:$N$59,MATCH($D$2&$H$2,数据底稿2!$A$50:$A$59,0),11),"/") -> 28.7万 | W29: =IFERROR(INDEX(数据底稿2!$A$50:$N$59,MATCH($D$2&$H$2,数据底稿2!$A$50:$A$59,0),12),"/") -> 3.9万 | Y29: 立邦 | AA29: 95
D30: 人均服务网点数 | G30: =IF(OR(C26=FALSE,C26="",ISERROR(C26)),"",IF(OR(G9="",ISERROR(G9)),"",IFERROR(IF(G9<=INDEX(数据底稿1!$I:$I,MATCH($D$2&"|"&$H$2&"|人均服务网点数",数据底稿1!$Z:$Z,0)),INDEX(数据底稿1!$L:$L,MATCH($D$2&"|"&$H$2&"|人均服务网点数",数据底稿1!$Z:$Z,0)),IF(G9<=INDEX(数据底稿1!$M:$M,MATCH($D$2&"|"&$H$2&"|人均服务网点数",数据底稿1!$Z:$Z,0)),INDEX(数据底稿1!$P:$P,MATCH($D$2&"|"&$H$2&"|人均服务网点数",数据底稿1!$Z:$Z,0)),IF(OR(INDEX(数据底稿1!$Q:$Q,MATCH($D$2&"|"&$H$2&"|人均服务网点数",数据底稿1!$Z:$Z,0))="",G9<=INDEX(数据底稿1!$Q:$Q,MATCH($D$2&"|"&$H$2&"|人均服务网点数",数据底稿1!$Z:$Z,0))),INDEX(数据底稿1!$T:$T,MATCH($D$2&"|"&$H$2&"|人均服务网点数",数据底稿1!$Z:$Z,0)),IFERROR(IF(INDEX(数据底稿1!$X:$X,MATCH($D$2&"|"&$H$2&"|人均服务网点数",数据底稿1!$Z:$Z,0))="","",INDEX(数据底稿1!$X:$X,MATCH($D$2&"|"&$H$2&"|人均服务网点数",数据底稿1!$Z:$Z,0))),"")))),""))) -> 人均服务网点数处于同类经销商中的领先水平，单兵服务密度极高，人员负荷处于满载状态。建议关注人效，防止服务质量下降。 | Y30: 其他主要竞品1 | AA30: 20
D31: 人效 | G31: =IF(OR(C26=FALSE,C26="",ISERROR(C26)),"",IF(OR(G10="",ISERROR(G10)),"",IFERROR(IF(G10<=INDEX(数据底稿1!$I:$I,MATCH($D$2&"|"&$H$2&"|人效",数据底稿1!$Z:$Z,0)),INDEX(数据底稿1!$L:$L,MATCH($D$2&"|"&$H$2&"|人效",数据底稿1!$Z:$Z,0)),IF(G10<=INDEX(数据底稿1!$M:$M,MATCH($D$2&"|"&$H$2&"|人效",数据底稿1!$Z:$Z,0)),INDEX(数据底稿1!$P:$P,MATCH($D$2&"|"&$H$2&"|人效",数据底稿1!$Z:$Z,0)),IF(OR(INDEX(数据底稿1!$Q:$Q,MATCH($D$2&"|"&$H$2&"|人效",数据底稿1!$Z:$Z,0))="",G10<=INDEX(数据底稿1!$Q:$Q,MATCH($D$2&"|"&$H$2&"|人效",数据底稿1!$Z:$Z,0))),INDEX(数据底稿1!$T:$T,MATCH($D$2&"|"&$H$2&"|人效",数据底稿1!$Z:$Z,0)),IFERROR(IF(INDEX(数据底稿1!$X:$X,MATCH($D$2&"|"&$H$2&"|人效",数据底稿1!$Z:$Z,0))="","",INDEX(数据底稿1!$X:$X,MATCH($D$2&"|"&$H$2&"|人效",数据底稿1!$Z:$Z,0))),"")))),""))) -> 人效处于同类经销商中的领先水平，人力资源利用充分，人均创造价值高。建议关注销售额整体构成，提升净利润水平。 | P31: 品类结构 （防水：砂浆：美缝：卷材：墙辅：胶业+管业） | U31: 渠道结构 （分销：零售：家装+工装） | Y31: 其他主要竞品2 | AA31: 70
D32: 乡镇覆盖率 | G32: =IF(OR(C26=FALSE,C26="",ISERROR(C26)),"",IF(OR(M10="",ISERROR(M10)),"",IFERROR(IF(M10<=INDEX(数据底稿1!$I:$I,MATCH($D$2&"|"&$H$2&"|乡镇覆盖率",数据底稿1!$Z:$Z,0)),INDEX(数据底稿1!$L:$L,MATCH($D$2&"|"&$H$2&"|乡镇覆盖率",数据底稿1!$Z:$Z,0)),IF(M10<=INDEX(数据底稿1!$M:$M,MATCH($D$2&"|"&$H$2&"|乡镇覆盖率",数据底稿1!$Z:$Z,0)),INDEX(数据底稿1!$P:$P,MATCH($D$2&"|"&$H$2&"|乡镇覆盖率",数据底稿1!$Z:$Z,0)),IF(OR(INDEX(数据底稿1!$Q:$Q,MATCH($D$2&"|"&$H$2&"|乡镇覆盖率",数据底稿1!$Z:$Z,0))="",M10<=INDEX(数据底稿1!$Q:$Q,MATCH($D$2&"|"&$H$2&"|乡镇覆盖率",数据底稿1!$Z:$Z,0))),INDEX(数据底稿1!$T:$T,MATCH($D$2&"|"&$H$2&"|乡镇覆盖率",数据底稿1!$Z:$Z,0)),IFERROR(IF(INDEX(数据底稿1!$X:$X,MATCH($D$2&"|"&$H$2&"|乡镇覆盖率",数据底稿1!$Z:$Z,0))="","",INDEX(数据底稿1!$X:$X,MATCH($D$2&"|"&$H$2&"|乡镇覆盖率",数据底稿1!$Z:$Z,0))),"")))),""))) -> 乡镇覆盖率处于同类经销商中的领先水平，乡镇市场渗透充分。建议关注乡镇网点的产值表现，制定差异化运营方案，优化产品和服务策略。 | P32: 优秀值 | Q32: =IFERROR(INDEX(数据底稿2!$A$50:$N$59,MATCH($D$2&$H$2,数据底稿2!$A$50:$A$59,0),13),"/") -> 33 : 44 : 7 : 10 : 2 : 4 | U32: 优秀值 | V32: =IFERROR(INDEX(数据底稿2!$A$50:$N$59,MATCH($D$2&$H$2,数据底稿2!$A$50:$A$59,0),14),"/") -> 93：04：03 | Y32: ……
D33: 单店产出 | G33: =IF(OR(C26=FALSE,C26="",ISERROR(C26)),"",IF(OR(M7="",ISERROR(M7)),"",IFERROR(IF(M7<=INDEX(数据底稿1!$I:$I,MATCH($D$2&"|"&$H$2&"|单店产出",数据底稿1!$Z:$Z,0)),INDEX(数据底稿1!$L:$L,MATCH($D$2&"|"&$H$2&"|单店产出",数据底稿1!$Z:$Z,0)),IF(M7<=INDEX(数据底稿1!$M:$M,MATCH($D$2&"|"&$H$2&"|单店产出",数据底稿1!$Z:$Z,0)),INDEX(数据底稿1!$P:$P,MATCH($D$2&"|"&$H$2&"|单店产出",数据底稿1!$Z:$Z,0)),IF(OR(INDEX(数据底稿1!$Q:$Q,MATCH($D$2&"|"&$H$2&"|单店产出",数据底稿1!$Z:$Z,0))="",M7<=INDEX(数据底稿1!$Q:$Q,MATCH($D$2&"|"&$H$2&"|单店产出",数据底稿1!$Z:$Z,0))),INDEX(数据底稿1!$T:$T,MATCH($D$2&"|"&$H$2&"|单店产出",数据底稿1!$Z:$Z,0)),IFERROR(IF(INDEX(数据底稿1!$X:$X,MATCH($D$2&"|"&$H$2&"|单店产出",数据底稿1!$Z:$Z,0))="","",INDEX(数据底稿1!$X:$X,MATCH($D$2&"|"&$H$2&"|单店产出",数据底稿1!$Z:$Z,0))),"")))),""))) -> 单店产值处于同类经销商中的领先水平，头部门店表现突出。建议分析头部门店成功经验，复制推广至其他门店，防范因过度依赖少数头部门店而导致的结构性风险。 | P33: 附加分指标评语 | Y33: ……
D34: 有效门店占比 | G34: =IF(OR(C26=FALSE,C26="",ISERROR(C26)),"",IF(OR(M8="",ISERROR(M8)),"",IFERROR(IF(M8<=INDEX(数据底稿1!$I:$I,MATCH($D$2&"|"&$H$2&"|有效门店占比",数据底稿1!$Z:$Z,0)),INDEX(数据底稿1!$L:$L,MATCH($D$2&"|"&$H$2&"|有效门店占比",数据底稿1!$Z:$Z,0)),IF(M8<=INDEX(数据底稿1!$M:$M,MATCH($D$2&"|"&$H$2&"|有效门店占比",数据底稿1!$Z:$Z,0)),INDEX(数据底稿1!$P:$P,MATCH($D$2&"|"&$H$2&"|有效门店占比",数据底稿1!$Z:$Z,0)),IF(OR(INDEX(数据底稿1!$Q:$Q,MATCH($D$2&"|"&$H$2&"|有效门店占比",数据底稿1!$Z:$Z,0))="",M8<=INDEX(数据底稿1!$Q:$Q,MATCH($D$2&"|"&$H$2&"|有效门店占比",数据底稿1!$Z:$Z,0))),INDEX(数据底稿1!$T:$T,MATCH($D$2&"|"&$H$2&"|有效门店占比",数据底稿1!$Z:$Z,0)),IFERROR(IF(INDEX(数据底稿1!$X:$X,MATCH($D$2&"|"&$H$2&"|有效门店占比",数据底稿1!$Z:$Z,0))="","",INDEX(数据底稿1!$X:$X,MATCH($D$2&"|"&$H$2&"|有效门店占比",数据底稿1!$Z:$Z,0))),"")))),""))) -> 有效门店占比处于同类经销商中的领先水平，网点拜访率及陈列合格率高，资源利用效率高。建议关注高拜访率门店的产值表现。 | P34: 会员活跃率 | R34: =IF(U6="","",IF(U6>=INDEX(数据底稿2!C4:K4,1,MATCH($D$2&$H$2,数据底稿2!$C$3:$K$3,0)),数据底稿2!$B$22,IF(U6>=INDEX(数据底稿2!C5:K5,1,MATCH($D$2&$H$2,数据底稿2!$C$3:$K$3,0)),数据底稿2!$C$22,IF(U6>=INDEX(数据底稿2!C6:K6,1,MATCH($D$2&$H$2,数据底稿2!$C$3:$K$3,0)),数据底稿2!$D$22,数据底稿2!$E$22)))) -> 会员活跃率接近参考值，仍有提升空间 | Y34: 计算输出
D35: 自有人员数量 | G35: =IF(OR(C26=FALSE,C26="",ISERROR(C26)),"",IF(OR(M9="",ISERROR(M9)),"",IFERROR(IF(M9<=INDEX(数据底稿1!$I:$I,MATCH($D$2&"|"&$H$2&"|自有人员数量",数据底稿1!$Z:$Z,0)),INDEX(数据底稿1!$L:$L,MATCH($D$2&"|"&$H$2&"|自有人员数量",数据底稿1!$Z:$Z,0)),IF(M9<=INDEX(数据底稿1!$M:$M,MATCH($D$2&"|"&$H$2&"|自有人员数量",数据底稿1!$Z:$Z,0)),INDEX(数据底稿1!$P:$P,MATCH($D$2&"|"&$H$2&"|自有人员数量",数据底稿1!$Z:$Z,0)),IF(OR(INDEX(数据底稿1!$Q:$Q,MATCH($D$2&"|"&$H$2&"|自有人员数量",数据底稿1!$Z:$Z,0))="",M9<=INDEX(数据底稿1!$Q:$Q,MATCH($D$2&"|"&$H$2&"|自有人员数量",数据底稿1!$Z:$Z,0))),INDEX(数据底稿1!$T:$T,MATCH($D$2&"|"&$H$2&"|自有人员数量",数据底稿1!$Z:$Z,0)),IFERROR(IF(INDEX(数据底稿1!$X:$X,MATCH($D$2&"|"&$H$2&"|自有人员数量",数据底稿1!$Z:$Z,0))="","",INDEX(数据底稿1!$X:$X,MATCH($D$2&"|"&$H$2&"|自有人员数量",数据底稿1!$Z:$Z,0))),"")))),""))) -> 自有人员数量处于同类经销商中的领先水平，具备深耕市场的团队基础。建议结合渠道发展合理分工，加强人员专业技能培训，提升团队整体素质；建立人员梯队建设计划，保障团队可持续发展。 | Y35: 我方市占率（vs竞品合计） | AA35: =AA27/SUM(AA27:AA33) -> 0.2739726
D36: 会员数量 | G36: =IF(OR(C26=FALSE,C26="",ISERROR(C26)),"",IF(OR(G11="",ISERROR(G11)),"",IFERROR(IF(G11<=INDEX(数据底稿1!$I:$I,MATCH($D$2&"|"&$H$2&"|会员数量",数据底稿1!$Z:$Z,0)),INDEX(数据底稿1!$L:$L,MATCH($D$2&"|"&$H$2&"|会员数量",数据底稿1!$Z:$Z,0)),IF(G11<=INDEX(数据底稿1!$M:$M,MATCH($D$2&"|"&$H$2&"|会员数量",数据底稿1!$Z:$Z,0)),INDEX(数据底稿1!$P:$P,MATCH($D$2&"|"&$H$2&"|会员数量",数据底稿1!$Z:$Z,0)),IF(OR(INDEX(数据底稿1!$Q:$Q,MATCH($D$2&"|"&$H$2&"|会员数量",数据底稿1!$Z:$Z,0))="",G11<=INDEX(数据底稿1!$Q:$Q,MATCH($D$2&"|"&$H$2&"|会员数量",数据底稿1!$Z:$Z,0))),INDEX(数据底稿1!$T:$T,MATCH($D$2&"|"&$H$2&"|会员数量",数据底稿1!$Z:$Z,0)),IFERROR(IF(INDEX(数据底稿1!$X:$X,MATCH($D$2&"|"&$H$2&"|会员数量",数据底稿1!$Z:$Z,0))="","",INDEX(数据底稿1!$X:$X,MATCH($D$2&"|"&$H$2&"|会员数量",数据底稿1!$Z:$Z,0))),"")))),""))) -> 会员数量处于同类经销商中的领先水平，市场影响力强，客户资源丰富。建议建立会员分级管理体系，提升高价值会员服务质量；制定会员活跃度提升计划，增强会员粘性。 | P36: 家装销售占比 | R36: =IF(U8="","",IF(U8>=INDEX(数据底稿2!C7:K7,1,MATCH($D$2&$H$2,数据底稿2!$C$3:$K$3,0)),数据底稿2!$B$23,IF(U8>=INDEX(数据底稿2!C8:K8,1,MATCH($D$2&$H$2,数据底稿2!$C$3:$K$3,0)),数据底稿2!$C$23,IF(U8>=INDEX(数据底稿2!C9:K9,1,MATCH($D$2&$H$2,数据底稿2!$C$3:$K$3,0)),数据底稿2!$D$23,数据底稿2!$E$23)))) -> 家装销售占比显著偏低，亟需开发家装渠道，如油工、设计带动等 | Y36: 最大竞品市占率 | AA36: =MAX(AA28:AA33)/SUM(AA27:AA33) -> 0.26027397
D37: 会员人均产值 | G37: =IF(OR(C26=FALSE,C26="",ISERROR(C26)),"",IF(OR(M11="",ISERROR(M11)),"",IFERROR(IF(M11<=INDEX(数据底稿1!$I:$I,MATCH($D$2&"|"&$H$2&"|会员人均产出",数据底稿1!$Z:$Z,0)),INDEX(数据底稿1!$L:$L,MATCH($D$2&"|"&$H$2&"|会员人均产出",数据底稿1!$Z:$Z,0)),IF(M11<=INDEX(数据底稿1!$M:$M,MATCH($D$2&"|"&$H$2&"|会员人均产出",数据底稿1!$Z:$Z,0)),INDEX(数据底稿1!$P:$P,MATCH($D$2&"|"&$H$2&"|会员人均产出",数据底稿1!$Z:$Z,0)),IF(OR(INDEX(数据底稿1!$Q:$Q,MATCH($D$2&"|"&$H$2&"|会员人均产出",数据底稿1!$Z:$Z,0))="",M11<=INDEX(数据底稿1!$Q:$Q,MATCH($D$2&"|"&$H$2&"|会员人均产出",数据底稿1!$Z:$Z,0))),INDEX(数据底稿1!$T:$T,MATCH($D$2&"|"&$H$2&"|会员人均产出",数据底稿1!$Z:$Z,0)),IFERROR(IF(INDEX(数据底稿1!$X:$X,MATCH($D$2&"|"&$H$2&"|会员人均产出",数据底稿1!$Z:$Z,0))="","",INDEX(数据底稿1!$X:$X,MATCH($D$2&"|"&$H$2&"|会员人均产出",数据底稿1!$Z:$Z,0))),"")))),""))) -> 会员人均产出处于同类经销商中的领先水平，核心会员粘性强、贡献大。建议与核心会员签订协议，建立长期合作关系，保证稳定性。 | Y37: 我方 vs 最大竞品倍率 | AA37: =IF(MAX(AA28:AA33)=0,"-",AA27/MAX(AA28:AA33)) -> 1.0526316
D38: 渠道数量 | G38: =IF(OR(C26=FALSE,C26="",ISERROR(C26)),"",IF(OR(G12="",ISERROR(G12)),"",IFERROR(IF(G12<INDEX(数据底稿1!$I:$I,MATCH($D$2&"|"&$H$2&"|渠道数量",数据底稿1!$Z:$Z,0)),INDEX(数据底稿1!$L:$L,MATCH($D$2&"|"&$H$2&"|渠道数量",数据底稿1!$Z:$Z,0)),IF(G12<INDEX(数据底稿1!$M:$M,MATCH($D$2&"|"&$H$2&"|渠道数量",数据底稿1!$Z:$Z,0)),INDEX(数据底稿1!$P:$P,MATCH($D$2&"|"&$H$2&"|渠道数量",数据底稿1!$Z:$Z,0)),IF(OR(INDEX(数据底稿1!$Q:$Q,MATCH($D$2&"|"&$H$2&"|渠道数量",数据底稿1!$Z:$Z,0))="",G12<INDEX(数据底稿1!$Q:$Q,MATCH($D$2&"|"&$H$2&"|渠道数量",数据底稿1!$Z:$Z,0))),INDEX(数据底稿1!$T:$T,MATCH($D$2&"|"&$H$2&"|渠道数量",数据底稿1!$Z:$Z,0)),IFERROR(IF(INDEX(数据底稿1!$X:$X,MATCH($D$2&"|"&$H$2&"|渠道数量",数据底稿1!$Z:$Z,0))="","",INDEX(数据底稿1!$X:$X,MATCH($D$2&"|"&$H$2&"|渠道数量",数据底稿1!$Z:$Z,0))),"")))),""))) -> 渠道数量处于同类经销商中的领先水平，业务结构健康多元，具备一定盈利能力和发展潜力，抗风险能力强。建议针对低产出渠道进行资源倾斜。 | P38: 家装公司产出/月 | R38: =IF(U10="","",IF(U10>=INDEX(数据底稿2!C10:K10,1,MATCH($D$2&$H$2,数据底稿2!$C$3:$K$3,0)),数据底稿2!$B$24,IF(U10>=INDEX(数据底稿2!C11:K11,1,MATCH($D$2&$H$2,数据底稿2!$C$3:$K$3,0)),数据底稿2!$C$24,IF(U10>=INDEX(数据底稿2!C12:K12,1,MATCH($D$2&$H$2,数据底稿2!$C$3:$K$3,0)),数据底稿2!$D$24,数据底稿2!$E$24)))) -> 单家装公司产出接近参考值，可持续挖掘单客价值 | Y38: 竞争格局评语
C39: 品类维度 | D39: 品类数量 | G39: =IF(OR(C26=FALSE,C26="",ISERROR(C26)),"",IF(OR(G13="",ISERROR(G13)),"",IFERROR(IF(G13<INDEX(数据底稿1!$I:$I,MATCH($D$2&"|"&$H$2&"|品类数量",数据底稿1!$Z:$Z,0)),INDEX(数据底稿1!$L:$L,MATCH($D$2&"|"&$H$2&"|品类数量",数据底稿1!$Z:$Z,0)),IF(G13<INDEX(数据底稿1!$M:$M,MATCH($D$2&"|"&$H$2&"|品类数量",数据底稿1!$Z:$Z,0)),INDEX(数据底稿1!$P:$P,MATCH($D$2&"|"&$H$2&"|品类数量",数据底稿1!$Z:$Z,0)),IF(OR(INDEX(数据底稿1!$Q:$Q,MATCH($D$2&"|"&$H$2&"|品类数量",数据底稿1!$Z:$Z,0))="",G13<INDEX(数据底稿1!$Q:$Q,MATCH($D$2&"|"&$H$2&"|品类数量",数据底稿1!$Z:$Z,0))),INDEX(数据底稿1!$T:$T,MATCH($D$2&"|"&$H$2&"|品类数量",数据底稿1!$Z:$Z,0)),IFERROR(IF(INDEX(数据底稿1!$X:$X,MATCH($D$2&"|"&$H$2&"|品类数量",数据底稿1!$Z:$Z,0))="","",INDEX(数据底稿1!$X:$X,MATCH($D$2&"|"&$H$2&"|品类数量",数据底稿1!$Z:$Z,0))),"")))),""))) -> 品类数量处于同类经销商中的领先水平，品类结构丰富，具备一站式综合服务基础，市场竞争力强。建议分级管理品类，明确利润品与销量品，保持品类活力。
C40: 公司维度 | D40: 坪效 | G40: =IF(OR(C26=FALSE,C26="",ISERROR(C26)),"",IF(OR(G15="",ISERROR(G15)),"",IFERROR(IF(G15<=INDEX(数据底稿1!$I:$I,MATCH($D$2&"|"&$H$2&"|坪效",数据底稿1!$Z:$Z,0)),INDEX(数据底稿1!$L:$L,MATCH($D$2&"|"&$H$2&"|坪效",数据底稿1!$Z:$Z,0)),IF(G15<=INDEX(数据底稿1!$M:$M,MATCH($D$2&"|"&$H$2&"|坪效",数据底稿1!$Z:$Z,0)),INDEX(数据底稿1!$P:$P,MATCH($D$2&"|"&$H$2&"|坪效",数据底稿1!$Z:$Z,0)),IF(OR(INDEX(数据底稿1!$Q:$Q,MATCH($D$2&"|"&$H$2&"|坪效",数据底稿1!$Z:$Z,0))="",G15<=INDEX(数据底稿1!$Q:$Q,MATCH($D$2&"|"&$H$2&"|坪效",数据底稿1!$Z:$Z,0))),INDEX(数据底稿1!$T:$T,MATCH($D$2&"|"&$H$2&"|坪效",数据底稿1!$Z:$Z,0)),IFERROR(IF(INDEX(数据底稿1!$X:$X,MATCH($D$2&"|"&$H$2&"|坪效",数据底稿1!$Z:$Z,0))="","",INDEX(数据底稿1!$X:$X,MATCH($D$2&"|"&$H$2&"|坪效",数据底稿1!$Z:$Z,0))),"")))),""))) -> 坪效处于同类经销商中的领先水平，仓储运营的精细化管理程度高，成本控制好。建议根据毛利润调整产品组合，持续优化。 | P40: 工单转化率 | R40: =IF(U13="","",IF(U13>=INDEX(数据底稿2!C16:K16,1,MATCH($D$2&$H$2,数据底稿2!$C$3:$K$3,0)),数据底稿2!$B$25,IF(U13>=INDEX(数据底稿2!C17:K17,1,MATCH($D$2&$H$2,数据底稿2!$C$3:$K$3,0)),数据底稿2!$C$25,IF(U13>=INDEX(数据底稿2!C18:K18,1,MATCH($D$2&$H$2,数据底稿2!$C$3:$K$3,0)),数据底稿2!$D$25,数据底稿2!$E$25)))) -> 工单转化率已达参考值，在维持转化率的同时关注工单质量 | Y40: =IF(AA37="","",IF(AA37>1.5,[1]数据底稿2!$B$30,IF(AND(AA37>=0.8,AA37<=1.5),[1]数据底稿2!$B$31,IF(AND(AA37>=0.5,AA37<0.8),[1]数据底稿2!$B$32,IF(AA37<0.5,[1]数据底稿2!$B$33,""))))) -> 竞争格局：势均力敌，激烈胶着
D41: 分销会次数 | G41: =IF(OR(C26=FALSE,C26="",ISERROR(C26)),"",IF(OR(G14="",ISERROR(G14)),"",IFERROR(IF(G14<=INDEX(数据底稿1!$I:$I,MATCH($D$2&"|"&$H$2&"|分销会次数",数据底稿1!$Z:$Z,0)),INDEX(数据底稿1!$L:$L,MATCH($D$2&"|"&$H$2&"|分销会次数",数据底稿1!$Z:$Z,0)),IF(G14<=INDEX(数据底稿1!$M:$M,MATCH($D$2&"|"&$H$2&"|分销会次数",数据底稿1!$Z:$Z,0)),INDEX(数据底稿1!$P:$P,MATCH($D$2&"|"&$H$2&"|分销会次数",数据底稿1!$Z:$Z,0)),IF(OR(INDEX(数据底稿1!$Q:$Q,MATCH($D$2&"|"&$H$2&"|分销会次数",数据底稿1!$Z:$Z,0))="",G14<=INDEX(数据底稿1!$Q:$Q,MATCH($D$2&"|"&$H$2&"|分销会次数",数据底稿1!$Z:$Z,0))),INDEX(数据底稿1!$T:$T,MATCH($D$2&"|"&$H$2&"|分销会次数",数据底稿1!$Z:$Z,0)),IFERROR(IF(INDEX(数据底稿1!$X:$X,MATCH($D$2&"|"&$H$2&"|分销会次数",数据底稿1!$Z:$Z,0))="","",INDEX(数据底稿1!$X:$X,MATCH($D$2&"|"&$H$2&"|分销会次数",数据底稿1!$Z:$Z,0))),"")))),""))) -> 分销会场次处于同类经销商中的领先水平，在激活分销网络上具备主动性，渠道维护积极。建议提升会议质量和针对性，增强会议效果，关注分销单店产值。
D42: 专业人士会议次数 | G42: =IF(OR(C26=FALSE,C26="",ISERROR(C26)),"",IF(OR(M14="",ISERROR(M14)),"",IFERROR(IF(M14<=INDEX(数据底稿1!$I:$I,MATCH($D$2&"|"&$H$2&"|专业人士会议次数",数据底稿1!$Z:$Z,0)),INDEX(数据底稿1!$L:$L,MATCH($D$2&"|"&$H$2&"|专业人士会议次数",数据底稿1!$Z:$Z,0)),IF(M14<=INDEX(数据底稿1!$M:$M,MATCH($D$2&"|"&$H$2&"|专业人士会议次数",数据底稿1!$Z:$Z,0)),INDEX(数据底稿1!$P:$P,MATCH($D$2&"|"&$H$2&"|专业人士会议次数",数据底稿1!$Z:$Z,0)),IF(OR(INDEX(数据底稿1!$Q:$Q,MATCH($D$2&"|"&$H$2&"|专业人士会议次数",数据底稿1!$Z:$Z,0))="",M14<=INDEX(数据底稿1!$Q:$Q,MATCH($D$2&"|"&$H$2&"|专业人士会议次数",数据底稿1!$Z:$Z,0))),INDEX(数据底稿1!$T:$T,MATCH($D$2&"|"&$H$2&"|专业人士会议次数",数据底稿1!$Z:$Z,0)),IFERROR(IF(INDEX(数据底稿1!$X:$X,MATCH($D$2&"|"&$H$2&"|专业人士会议次数",数据底稿1!$Z:$Z,0))="","",INDEX(数据底稿1!$X:$X,MATCH($D$2&"|"&$H$2&"|专业人士会议次数",数据底稿1!$Z:$Z,0))),"")))),""))) -> 专业人士会议场次处于同类经销商中的领先水平，会议开展积极，客情维护到位。 建议关注会员人均产出，防范资源浪费。 | P42: 月均工单数量 | R42: =IF(U15="","",IF(U15>=INDEX(数据底稿2!C13:K13,1,MATCH($D$2&$H$2,数据底稿2!$C$3:$K$3,0)),数据底稿2!$B$26,IF(U15>=INDEX(数据底稿2!C14:K14,1,MATCH($D$2&$H$2,数据底稿2!$C$3:$K$3,0)),数据底稿2!$C$26,IF(U15>=INDEX(数据底稿2!C15:K15,1,MATCH($D$2&$H$2,数据底稿2!$C$3:$K$3,0)),数据底稿2!$D$26,数据底稿2!$E$26)))) -> 月均工单数量接近参考值，可进一步优化服务流程
...

Sheet 数据底稿1
A1: 东方雨虹经销商定量诊断评分 · 数据底稿总表
A2: 使用说明：本表所有指标的区间取值、得分及评语，均可被9张诊断表通过 INDEX/MATCH 公式直接引用。修改本表数据后，诊断表自动同步。区间①~③的"上限值"即为临界值（实际值 < 上限值时适用该区间）；区间④为最高档无上限。
A3: 基本信息 | I3: 区间 ①（实际值 ≤ 区间①上限） | M3: 区间 ②（区间①上限 < 实际值 ≤ 区间②上限） | Q3: 区间 ③（区间②上限 < 实际值 ≤ 区间③上限） | U3: 区间 ④（> 区间③上限，最高档） | Y3: 其他
A4: 城市等级 | B4: 坎级 | C4: 层级 | D4: 子维度 | E4: 指标名称 | F4: 单位 | G4: 权重 | H4: 优秀值 （P70） | I4: 区间① 上限值 | J4: 区间① 系数/得分 | K4: 区间① 计分说明 | L4: 区间① 评语 | M4: 区间② 上限值 | N4: 区间② 系数/得分 | O4: 区间② 计分说明 | P4: 区间② 评语 | Q4: 区间③ 上限值 | R4: 区间③ 系数/得分 | S4: 区间③ 计分说明 | T4: 区间③ 评语 | U4: 区间④ 档位/上限值 | V4: 区间④ 系数/得分 | W4: 区间④ 计分说明 | X4: 区间④ 评语 | Y4: 特殊规则/备注 | Z4: 复合键 （查询用）
A5: 超特 | B5: 300W-1000W | C5: 增长层 | D5: 生意总体 | E5: 合同达成率 | F5: % | G5: 0.1 | H5: 1 | I5: 0.85 | J5: 0.1 | K5: 实际值×0.1（得分随实际值浮动） | L5: 合同达成率低于85%，履约情况需重点改善，严重影响合作稳定性。建议深入复盘分析未达成原因，制定详细改进计划并跟踪落实，确保合同履约执行到位。 | M5: 0.9 | N5: 0.11 | O5: 实际值×0.11 | P5: 合同达成率低于90%，合同履约不足，存在较大改善空间。建议重点关注低达成率品类，分析原因并制定改善计划。 | Q5: 1 | R5: 0.12 | S5: 实际值×0.12 | T5: 全年合同尚未达百，但整体达成情况较好，可能存在部分合同履约不足。建议关注单份合同达成差异，制定针对性改进措施。 | U5: — | V5: 0.144 | W5: 固定封顶，最高14.4分 | X5: 全年合同达百，整体表现优异。建议深入分析单份合同达成差异，防范个别合同达成不力带来的风险。 | Y5: 比例计分，区间上限即为各档临界值 | Z5: 超特|300W-1000W|合同达成率
A6: 超特 | B6: 300W-1000W | C6: 增长层 | D6: 生意总体 | E6: 销售增长率 | F6: % | G6: 0.1 | H6: 0.34 | I6: -1e-17 | J6: 0 | K6: 负增长超过阈值，得0分 | L6: 销售呈现负增长，市场竞争力弱。建议深入分析市场环境和竞争态势，制定针对性营销策略，同时对负增长品类进行专项评估，调整产品结构。 | M6: 0.15 | N6: 0.04 | O6: 固定系数，×100得4分 | P6: 销售增长率处于同类经销商中的中等偏下水平，增长动力有待加强。建议聚焦低增长品类，分析原因并制定提升策略。 | Q6: 0.34 | R6: 0.07 | S6: 固定系数，×100得7分 | T6: 销售增长率处于同类经销商中的中等偏上水平，增长态势良好。建议持续关注品类增长，挖掘潜力品类，提升增长空间。 | U6: — | V6: 0.1 | W6: 固定系数，×100得10分 | X6: 销售增长率处于同类经销商中的领先水平，增长动力强劲。建议关注各品类的增长表现，识别增长引擎品类，制定可持续增长策略，避免短期波动影响长期发展。 | Z6: 超特|300W-1000W|销售增长率
A7: 超特 | B7: 300W-1000W | C7: 增长层 | D7: 分销 | E7: 网点数量 | F7: 个 | G7: 0.058 | H7: 208个 | I7: 36.5 | J7: 30 | K7: 固定30分 | L7: 网点数量处于同类经销商中的末位水平，网点数量严重不足，网络基础薄弱。建议快速制定网点开发计划，加快拓展步伐，优先覆盖重点区域，并建立网点建设进度跟踪机制，确保计划落地。 | M7: 114 | N7: 50 | O7: 固定50分 | P7: 网点数量处于同类经销商中的中等偏下水平，网点数量少，网络覆盖不足。建议制定网点拓展计划，持续推进网点开发，填补空白区域，逐步完善网络布局。 | Q7: 208.3 | R7: 70 | S7: 固定70分 | T7: 网点数量处于同类经销商中的中等偏上水平，网络布局合理。建议在稳定数量的同时提升网点质量，聚焦单店产值和有效门店占比提升，优化网点结构。 | U7: ≥208.3 | V7: 90 | W7: 固定90分（满分） | X7: 网点数量处于同类经销商中的领先水平，网点覆盖广泛，网络基础扎实。建议重点提升单店产值和核心店占比，优化网点质量；同时建立网点分级管理体系，提高网点运营效率。 | Z7: 超特|300W-1000W|网点数量
A8: 超特 | B8: 300W-1000W | C8: 增长层 | D8: 分销 | E8: 核心店数量占比 | F8: % | G8: 0.043 | H8: 0.214 | I8: 0.066 | J8: 30 | K8: 固定30分 | L8: 核心店数量占比处于同类经销商中的末位水平，分销渠道结构极不稳定，核心网点建设严重不足，增长依赖低产值网点。建议分级管理，紧急选拔有潜力门店进行重点培育，打造核心店；学习优秀经销商核心店建设经验，快速复制；建立核心店建设专项考核机制，确保建设效果。 | M8: 0.148 | N8: 50 | O8: 固定50分 | P8: 核心店数量占比处于同类经销商中的中等偏下水平，分销渠道结构不稳定，核心网点建设不足，市场支撑能力弱。建议持续提升网点质量，建立核心店运营标准，培育更多核心店。 | Q8: 0.214 | R8: 70 | S8: 固定70分 | T8: 核心店数量占比处于同类经销商中的中等偏上水平，分销渠道结构稳定，核心店占比相对健康。建议关注核心店达成，建立核心店培育与退出机制，持续提升核心店质量，稳定增长基础。 | U8: ≥21.4% | V8: 90 | W8: 固定90分（满分） | X8: 核心店数量占比处于同类经销商中的领先水平，核心资源集中，分销渠道增长由核心店驱动，市场竞争力强。建议持续关注核心店达成情况，保持增长动力。 | Z8: 超特|300W-1000W|核心店数量占比
A9: 超特 | B9: 300W-1000W | C9: 增长层 | D9: 分销 | E9: 有效门店占比 | F9: % | G9: 0.13 | H9: 0.946 | I9: 0.762 | J9: 30 | K9: 固定30分 | L9: 有效门店占比处于同类经销商中的末位水平，建议安排专人定时进行拜访，完善分销管理流程；对低效门店进行全面评估，制定关停并转计划，集中资源提升保留门店的运营效率。 | M9: 0.918 | N9: 50 | O9: 固定50分 | P9: 有效门店占比处于同类经销商中的中等偏下水平，存在部分“沉睡”门店。建议提升拜访率，激活沉睡门店，避免分销资源浪费；同时对低效门店进行评估，制定整改或淘汰计划。 | Q9: 0.946 | R9: 70 | S9: 固定70分 | T9: 有效门店占比处于同类经销商中的中等偏上水平，网点拜访率及陈列合格率较高，大部分门店运营有效，存在少量低效门店。建议对低效门店进行整改或优化，提升整体有效性。 | U9: ≥94.6% | V9: 90 | W9: 固定90分（满分） | X9: 有效门店占比处于同类经销商中的领先水平，网点拜访率及陈列合格率高，资源利用效率高。建议关注高拜访率门店的产值表现。 | Z9: 超特|300W-1000W|有效门店占比
A10: 超特 | B10: 300W-1000W | C10: 增长层 | D10: 分销 | E10: 人均服务网点数 | F10: 个 | G10: 0.048 | H10: 76.6个 | I10: 33.2 | J10: 30 | K10: 固定30分 | L10: 人均服务网点数处于同类经销商中的末位水平，人员服务密度严重不足，单点人力服务成本高。建议重新设定人员服务网点考核指标，提升人员利用效率。 | M10: 59.3 | N10: 50 | O10: 固定50分 | P10: 人均服务网点数处于同类经销商中的中等偏下水平，单兵服务半径较小，人力资源利用不充分。建议提升网点数量，释放人员效能。 | Q10: 76.6 | R10: 70 | S10: 固定70分 | T10: 人均服务网点数处于同类经销商中的中等偏上水平，管理半径相对合理。建议持续关注人效，优化资源配置。 | U10: ≥76.6 | V10: 90 | W10: 固定90分（满分） | X10: 人均服务网点数处于同类经销商中的领先水平，单兵服务密度极高，人员负荷处于满载状态。建议关注人效，防止服务质量下降。 | Z10: 超特|300W-1000W|人均服务网点数
A11: 超特 | B11: 300W-1000W | C11: 增长层 | D11: 分销 | E11: 自有人员数量 | F11: 个 | G11: 0.024 | H11: 3个 | I11: 1 | J11: 30 | K11: 固定30分 | L11: 自有人员数量处于同类经销商中的末位水平，自有销售人员严重不足，业务开拓与网络维护能力严重受限。建议制定招聘计划，快速补充人员。 | M11: 2 | N11: 50 | O11: 固定50分 | P11: 自有人员数量处于同类经销商中的中等偏下水平，自有人员力量薄弱，覆盖与服务能力不足。建议结合人效和渠道需求，制定人员招聘计划，补充团队力量。 | Q11: 3 | R11: 70 | S11: 固定70分 | T11: 自有人员数量处于同类经销商中的中等偏上水平，具备基础的覆盖保障能力。建议聚焦重点渠道，优化人员配置。 | U11: ≥3 | V11: 90 | W11: 固定90分（满分） | X11: 自有人员数量处于同类经销商中的领先水平，具备深耕市场的团队基础。建议结合渠道发展合理分工，加强人员专业技能培训，提升团队整体素质；建立人员梯队建设计划，保障团队可持续发展。 | Z11: 超特|300W-1000W|自有人员数量
A12: 超特 | B12: 300W-1000W | C12: 增长层 | D12: 分销 | E12: 人效 | F12: 万元/人 | G12: 0.072 | H12: 511.8万/人 | I12: 277.2 | J12: 30 | K12: 固定30分 | L12: 人效处于同类经销商中的末位水平，可能存在经营亏损风险。建议关注如何提升销售额或考虑人员调整，建立明确的绩效考核和激励机制；同时加强人员培训，提升专业技能和工作效率。 | M12: 427.5 | N12: 50 | O12: 固定50分 | P12: 人效处于同类经销商中的中等偏下水平，人均产出不足，无法满足当前生意规模的需求。建议优化工作流程，消除无效劳动；建立绩效考核机制，激发人员工作积极性。 | Q12: 511.8 | R12: 70 | S12: 固定70分 | T12: 人效处于同类经销商中的中等偏上水平，基本满足当前生意规模的需求。建议分析高绩效人员工作方法，在团队内推广，持续优化人员产出，提升盈利能力。 | U12: ≥511.8 | V12: 90 | W12: 固定90分（满分） | X12: 人效处于同类经销商中的领先水平，人力资源利用充分，人均创造价值高。建议关注销售额整体构成，提升净利润水平。 | Z12: 超特|300W-1000W|人效
A13: 超特 | B13: 300W-1000W | C13: 增长层 | D13: 分销 | E13: 乡镇覆盖率 | F13: % | G13: 0.01 | H13: 1 | I13: 0.818 | J13: 30 | K13: 固定30分 | L13: 乡镇覆盖率处于同类经销商中的末位水平，乡镇覆盖极少，下沉市场开拓严重不足。建议制定乡镇市场专项开拓计划，快速布局；简化乡镇市场进入流程，降低开拓难度；建立乡镇市场开拓激励机制，加快开拓进度。 | M13: 0.909 | N13: 50 | O13: 固定50分 | P13: 乡镇覆盖率处于同类经销商中的中等水平，乡镇覆盖良好，布局较为均衡。建议建议制定乡镇开拓计划，筛选空白重点乡镇，逐步扩大乡镇覆盖范围，持续完善乡镇网络。 | Q13: 1 | R13: 70 | S13: 固定70分（本指标最高档，无第四档） | T13: 乡镇覆盖率处于同类经销商中的领先水平，乡镇市场渗透充分。建议关注乡镇网点的产值表现，制定差异化运营方案，优化产品和服务策略。 | U13: — | X13: 乡镇覆盖率处于同类经销商中的领先水平，乡镇市场渗透充分。建议关注乡镇网点的产值表现，制定差异化运营方案，优化产品和服务策略。 | Y13: 仅三档，满分系数70（非90） | Z13: 超特|300W-1000W|乡镇覆盖率
A14: 超特 | B14: 300W-1000W | C14: 增长层 | D14: 分销 | E14: 单店产出 | F14: 万元 | G14: 0.095 | H14: 8.4万 | I14: 2.8 | J14: 30 | K14: 固定30分 | L14: 单店产值处于同类经销商中的末位水平，门店产出普遍偏低。建议全面诊断门店运营问题，制定系统性提升方案；加强门店陈列、促销和服务管理，提升单店产出；建立门店运营督导机制，确保改进措施执行到位。 | M14: 3.7 | N14: 50 | O14: 固定50分 | P14: 单店产值处于同类经销商中的中等偏下水平，门店之间产值差异较大，整体水平偏低，单店运营效率有待提升。建议提升铺货率和拜访频次，激活低效门店。 | Q14: 8.4 | R14: 70 | S14: 固定70分 | T14: 单店产值处于同类经销商中的中等偏上水平，网络基础较好。大部分门店运营正常，少数门店产值偏低，建议聚焦低产值网点，提升铺货率和销售能力。 | U14: ≥8.4 | V14: 90 | W14: 固定90分（满分） | X14: 单店产值处于同类经销商中的领先水平，头部门店表现突出。建议分析头部门店成功经验，复制推广至其他门店，防范因过度依赖少数头部门店而导致的结构性风险。 | Y14: 权重由9.6%修正为9.5%，修正权重合计为100% | Z14: 超特|300W-1000W|单店产出
A15: 超特 | B15: 300W-1000W | C15: 增长层 | D15: 零售 | E15: 会员数量 | F15: 人 | G15: 0.035 | H15: 54人 | I15: 25 | J15: 30 | K15: 固定30分 | L15: 会员数量处于同类经销商中的末位水平，客户数量严重缺失，市场影响力弱。建议制定会员快速发展计划，通过多种渠道吸纳会员；建立会员入门优惠机制，降低会员加入门槛；加强会员服务基础建设，提升会员留存率。 | M15: 38 | N15: 50 | O15: 固定50分 | P15: 会员数量处于同类经销商中的中等偏下水平，客户基础薄弱，尚未形成规模。建议制定会员发展计划，通过工人会和小区推广等形式，扩大会员规模；建立会员服务体系，提升会员满意度和忠诚度。 | Q15: 54 | R15: 70 | S15: 固定70分 | T15: 会员数量处于同类经销商中的中等偏上水平，客户基础较好，具备零售业务基础。建议持续挖掘会员价值，提升转化率。 | U15: ≥54 | V15: 90 | W15: 固定90分（满分） | X15: 会员数量处于同类经销商中的领先水平，市场影响力强，客户资源丰富。建议建立会员分级管理体系，提升高价值会员服务质量；制定会员活跃度提升计划，增强会员粘性。 | Z15: 超特|300W-1000W|会员数量
A16: 超特 | B16: 300W-1000W | C16: 增长层 | D16: 零售 | E16: 会员人均产出 | F16: 万元/人 | G16: 0.015 | H16: 0.59万/人 | I16: 0.222 | J16: 30 | K16: 固定30分 | L16: 会员人均产出处于同类经销商中的末位水平，客户价值低，消费转化困难。建议安排专人负责，勤沟通，多开展培训会、订货会等，制定会员消费激励计划，提高会员消费频次和客单价。 | M16: 0.354 | N16: 50 | O16: 固定50分 | P16: 会员人均产出处于同类经销商中的中等偏下水平，价值转化不足，会员消费频次低。建议多开展培训会、订货会等，建立会员激励机制，提高会员消费积极性。 | Q16: 0.594 | R16: 70 | S16: 固定70分 | T16: 会员人均产出处于同类经销商中的中等偏上水平，会员产出良好，贡献稳定，高价值会员占比有待提升。建议建立会员价值提升机制，持续挖掘会员潜在价值；识别高潜力会员，制定专项服务计划。 | U16: ≥0.594 | V16: 90 | W16: 固定90分（满分） | X16: 会员人均产出处于同类经销商中的领先水平，核心会员粘性强、贡献大。建议与核心会员签订协议，建立长期合作关系，保证稳定性。 | Z16: 超特|300W-1000W|会员人均产出
A17: 超特 | B17: 300W-1000W | C17: 增长层 | D17: 渠道均衡发展 | E17: 渠道数量 | F17: 个 | G17: 0.06 | H17: 4个 | I17: 2 | J17: 20 | K17: 固定20分 | L17: 渠道数量处于同类经销商中的末位水平，业务结构单一，渠道建设严重不足。抗风险能力弱。建议拓展多元化渠道，丰富渠道结构；加强与现有渠道的深度合作，提升渠道效益。 | M17: 3 | N17: 70 | O17: 固定70分 | P17: 渠道数量处于同类经销商中的中等偏下水平，渠道类型少，抗风险能力不足。建议拓展多元化渠道，丰富渠道结构。 | Q17: 4 | R17: 90 | S17: 固定90分 | T17: 渠道数量处于同类经销商中的中等偏上水平，具备一定的抗风险能力。建议结合当地及自身情况，评估是否拓展新渠道；同时评估低效渠道改进空间，优化渠道结构。 | U17: ≧4 | V17: 90 | W17: 固定90分 | X17: 渠道数量处于同类经销商中的领先水平，业务结构健康多元，具备一定盈利能力和发展潜力，抗风险能力强。建议针对低产出渠道进行资源倾斜。 | Y17: 四档，得分跨度较大（20/70/90），区间③和区间④分值均为90分。 | Z17: 超特|300W-1000W|渠道数量
A18: 超特 | B18: 300W-1000W | C18: 增长层 | D18: 品类均衡发展 | E18: 品类数量 | F18: 个 | G18: 0.06 | H18: 4个 | I18: 2 | J18: 20 | K18: 固定20分（品类数<2个） | L18: 品类数量处于同类经销商中的末位水平，品类结构单一，客单价和盈利能力可能陷入瓶颈。建议结合当地市场需求，增加新品，提升品类丰富度和盈利能力。 | M18: 3 | N18: 50 | O18: 固定50分（2≤品类数<3个） | P18: 品类数量处于同类经销商中的中等偏下水平，品类偏少，综合服务能力不足。建议适当增加新品类，丰富产品结构，提升竞争力。 | Q18: 4 | R18: 70 | S18: 固定70分（3≤品类数<4个） | T18: 品类数量处于同类经销商中的中等偏上水平，具备基础的综合服务能力，建议结合产品销售增长情况，评估是否增加新品。 | U18: — | V18: 90 | W18: 固定90分（品类数≥4个） | X18: 品类数量处于同类经销商中的领先水平，品类结构丰富，具备一站式综合服务基础，市场竞争力强。建议分级管理品类，明确利润品与销量品，保持品类活力。 | Y18: 四档，20/50/70/90 | Z18: 超特|300W-1000W|品类数量
A19: 超特 | B19: 300W-1000W | C19: 支撑层 | D19: 会议场次 | E19: 分销会次数 | F19: 次 | G19: 0.015 | H19: 2次 | I19: 1 | J19: 30 | K19: 固定30分 | L19: 分销会场次处于同类经销商中的末位水平，与分销渠道的互动极度缺乏，渠道可能存在失联风险。建议结合门店拜访计划，制定最低会议频次标准，确保基本沟通；同时建立渠道反馈机制，及时了解渠道需求。 | M19: 2 | N19: 50 | O19: 固定50分 | P19: 分销会场次处于同类经销商中的中等偏下水平，渠道沟通不足，难以维系渠道粘性。建议结合销售节奏，制定分销会议计划，增加会议频次。 | Q19: 4 | R19: 70 | S19: 固定70分 | T19: 分销会场次处于同类经销商中的中等偏上水平，渠道粘性较强。建议聚焦核心店和有效门店，提升会议质量。 | U19: ≥4 | V19: 90 | W19: 固定90分（满分） | X19: 分销会场次处于同类经销商中的领先水平，在激活分销网络上具备主动性，渠道维护积极。建议提升会议质量和针对性，增强会议效果，关注分销单店产值。 | Z19: 超特|300W-1000W|分销会次数
A20: 超特 | B20: 300W-1000W | C20: 支撑层 | D20: 会议场次 | E20: 专业人士会议次数 | F20: 次 | G20: 0.035 | H20: 14次 | I20: 5 | J20: 30 | K20: 固定30分 | L20: 专业人士会议场次处于同类经销商中的末位水平，客情维护严重缺失，会员关系薄弱。建议制定专业人士会议计划，定期开展会议，加强会员沟通。 | M20: 8 | N20: 50 | O20: 固定50分 | P20: 专业人士会议场次处于同类经销商中的中等偏下水平，客情维护不足。建议聚焦新会员和低黏度会员，增强互动。 | Q20: 14 | R20: 70 | S20: 固定70分 | T20: 专业人士会议场次处于同类经销商中的中等偏上水平，会议开展良好，会员关系稳定。建议关注会员人均产出，提升低产出会员。 | U20: ≥14 | V20: 90 | W20: 固定90分（14~40次区间满分） | X20: 专业人士会议场次处于同类经销商中的领先水平，会议开展积极，客情维护到位。 建议关注会员人均产出，防范资源浪费。 | Y20: ⚠️ 特殊规则：次数>40次视为数据异常，得分回退至50分，函数中需单独处理 | Z20: 超特|300W-1000W|专业人士会议次数
A21: 超特 | B21: 300W-1000W | C21: 支撑层 | D21: 仓储效率 | E21: 坪效 | F21: 万元/㎡ | G21: 0.03 | H21: 1.25万/平方米 | I21: 0.61 | J21: 30 | K21: 固定30分 | L21: 坪效处于同类经销商中的末位水平，运营成本高，仓储可能已成为高成本负担。建议优化库存管理，调整产品结构；关注坪效指标，持续提升空间利用效率。 | M21: 0.94 | N21: 50 | O21: 固定50分 | P21: 坪效处于同类经销商中的中等偏下水平，仓储运营管理粗放，表明成本控制能力不足。建议调整产品结构，提升仓储效率。 | Q21: 1.25 | R21: 70 | S21: 固定70分 | T21: 坪效处于同类经销商中的中等偏上水平，仓储利用与成本控制良好。建议根据产品周转率优化仓储布局，聚焦低周转率产品，提升空间效率。 | U21: ≥1.25 | V21: 90 | W21: 固定90分（满分） | X21: 坪效处于同类经销商中的领先水平，仓储运营的精细化管理程度高，成本控制好。建议根据毛利润调整产品组合，持续优化。 | Z21: 超特|300W-1000W|坪效
A22: 超特 | B22: 300W-1000W | C22: 支撑层 | D22: 数字化水平 | E22: 数字化水平 | F22: a/b/c/d档 | G22: 0.02 | H22: a档 | I22: d | J22: 0 | K22: 未采用数字化系统，0分 | L22: 数字化水平处于同类经销商中的末位水平，无系统，管理方式原始，数据资产缺失，管理风险高，数据价值被浪费。建议引入基础数字化管理工具，加强人员数字化技能培训，快速推动数字化转型。 | M22: a | N22: 30 | O22: 固定30分（进销存系统） | P22: 数字化水平处于同类经销商中的中等偏下水平，数字化应用停留在记账层面，仍以传统管理方式为主，数据价值可能被浪费。建议引入数字化管理工具，提升管理效率和风险控制能力。 | Q22: b | R22: 70 | S22: 固定70分（数据分析能力） | T22: 数字化水平处于同类经销商中的中等偏上水平，已开始利用数据进行管理。建议建立数据资产体系，提升数据价值。 | U22: c | V22: 90 | W22: 固定90分（c档，指标洞察能力，满分） | X22: 数字化水平处于同类经销商中的领先水平，具备数据驱动决策能力。建议加强数据分析能力建设，用数据指导经营，提升决策效率。 | Y22: 字母档位评级，非数值区间；c最高（指标洞察），d最低 | Z22: 超特|300W-1000W|数字化水平
A23: 超特 | B23: 300W-1000W | C23: 意愿层 | D23: — | E23: 活动参与度 | F23: a/b/c档 | G23: 0.015 | H23: A档 | I23: c | J23: 20 | K23: 固定20分（基本不参与） | L23: 活动参与度处于同类经销商中的末位水平，活动参与积极性低，意愿差。建议与经销商勤沟通，提前沟通活动重要性和利益点；建立活动参与考核和激励机制，提升参与积极性。 | M23: b | N23: 60 | O23: 固定60分（一般参与） | P23: 活动参与度处于同类经销商中的中等偏下水平，参与积极性不足。建议与经销商勤沟通，找出活动参与度低的原因，提升活动参与意愿。 | Q23: a | R23: 90 | S23: 固定90分（积极参与，最高档） | T23: 活动参与度处于同类经销商中的中等偏上水平，参与意愿较强。建议建立活动总结机制，持续优化活动参与质量。 | U23: — | X23: 活动参与度处于同类经销商中的领先水平，活动配合积极，市场响应及时。建议关注活动执行效果，提升活动价值。 | Z23: 超特|300W-1000W|活动参与度
A24: 超特 | B24: 300W-1000W | C24: 意愿层 | D24: — | E24: 经营意愿 | F24: a/b/c档 | G24: 0.02 | H24: a档 | I24: c | J24: 20 | K24: 固定20分（计划放弃） | L24: 经营意愿处于同类经销商中的末位水平，对品牌信息不足，合作稳定性低。建议加强深度沟通，了解顾虑并提供解决方案，逐步建立信心。 | M24: b | N24: 60 | O24: 固定60分（一般配合） | P24: 经营意愿处于同类经销商中的中等偏下水平，经营积极性不足。建议与经销商勤沟通，找出经营意愿低的原因，寻找提升意愿的突破口。 | Q24: a | R24: 90 | S24: 固定90分（强烈经营意愿，最高档） | T24: 经营意愿处于同类经销商中的中等偏上水平，合作意愿较强。建议与经销商勤沟通，关注经营动态，及时响应需求。 | U24: — | X24: 经营意愿处于同类经销商中的领先水平，对于品牌经营信心充足，愿意配合公司积极开展市场活动，并投入人力物力等资源开展经营。建议保持沟通，深化合作关系。 | Z24: 超特|300W-1000W|经营意愿
A25: 超特 | B25: 300W-1000W | C25: 意愿层 | D25: — | E25: 文化认知度 | F25: a/b/c档 | G25: 0.015 | H25: A档 | I25: c | J25: 20 | K25: 固定20分（不认同） | L25: 文化认知度处于同类经销商中的末位水平，文化认知度薄弱，文化认同感低。建议与经销商勤沟通，建立文化沟通机制，及时传递文化理念；通过文化践行活动，促进文化认同。 | M25: b | N25: 60 | O25: 固定60分（了解认同） | P25: 文化认知度处于同类经销商中的中等偏下水平，文化理解不深，认同不足。建议加强企业文化宣导，提升文化认知度。 | Q25: a | R25: 90 | S25: 固定90分（高度认同品牌文化，最高档） | T25: 文化认知度处于同类经销商中的中等偏上水平，文化认同情况良好。建议加强企业文化培训，深化文化理解。 | U25: — | X25: 文化认知度处于同类经销商中的领先水平，对企业文化清晰认知和认同，价值观一致，合作基础稳固，并在日常市场经营活动中积极践行。建议积极传播企业文化，发挥示范作用。 | Z25: 超特|300W-1000W|文化认知度
A26: 超特 | B26: 1000W-2000W | C26: 增长层 | D26: 生意总体 | E26: 合同达成率 | F26: % | G26: 0.1 | H26: 1 | I26: 0.85 | J26: 0.1 | K26: 实际值×0.1（得分随实际值浮动） | L26: 合同达成率低于85%，履约情况需重点改善，严重影响合作稳定性。建议深入复盘分析未达成原因，制定详细改进计划并跟踪落实，确保合同履约执行到位。 | M26: 0.9 | N26: 0.11 | O26: 实际值×0.11 | P26: 合同达成率低于90%，合同履约不足，存在较大改善空间。建议重点关注低达成率品类，分析原因并制定改善计划。 | Q26: 1 | R26: 0.12 | S26: 实际值×0.12 | T26: 全年合同尚未达百，但整体达成情况较好，可能存在部分合同履约不足。建议关注单份合同达成差异，制定针对性改进措施。 | U26: — | V26: 0.144 | W26: 固定封顶，最高14.4分 | X26: 全年合同达百，整体表现优异。建议深入分析单份合同达成差异，防范个别合同达成不力带来的风险。 | Y26: 比例计分，区间上限即为各档临界值 | Z26: 超特|1000W-2000W|合同达成率
A27: 超特 | B27: 1000W-2000W | C27: 增长层 | D27: 生意总体 | E27: 销售增长率 | F27: % | G27: 0.1 | H27: 0.259 | I27: -1e-17 | J27: 0 | K27: 负增长超过阈值，得0分 | L27: 销售呈现负增长，市场竞争力弱。建议深入分析市场环境和竞争态势，制定针对性营销策略，同时对负增长品类进行专项评估，调整产品结构。 | M27: 0.0906 | N27: 0.04 | O27: 固定系数，×100得4分 | P27: 销售增长率处于同类经销商中的中等偏下水平，增长动力有待加强。建议聚焦低增长品类，分析原因并制定提升策略。 | Q27: 0.2592 | R27: 0.07 | S27: 固定系数，×100得7分 | T27: 销售增长率处于同类经销商中的中等偏上水平，增长态势良好。建议持续关注品类增长，挖掘潜力品类，提升增长空间。 | U27: — | V27: 0.1 | W27: 固定系数，×100得10分 | X27: 销售增长率处于同类经销商中的领先水平，增长动力强劲。建议关注各品类的增长表现，识别增长引擎品类，制定可持续增长策略，避免短期波动影响长期发展。 | Z27: 超特|1000W-2000W|销售增长率
A28: 超特 | B28: 1000W-2000W | C28: 增长层 | D28: 分销 | E28: 网点数量 | F28: 个 | G28: 0.0405 | H28: 368个 | I28: 27 | J28: 30 | K28: 固定30分 | L28: 网点数量处于同类经销商中的末位水平，网点数量严重不足，网络基础薄弱。建议快速制定网点开发计划，加快拓展步伐，优先覆盖重点区域，并建立网点建设进度跟踪机制，确保计划落地。 | M28: 212 | N28: 50 | O28: 固定50分 | P28: 网点数量处于同类经销商中的中等偏下水平，网点数量少，网络覆盖不足。建议制定网点拓展计划，持续推进网点开发，填补空白区域，逐步完善网络布局。 | Q28: 368 | R28: 70 | S28: 固定70分 | T28: 网点数量处于同类经销商中的中等偏上水平，网络布局合理。建议在稳定数量的同时提升网点质量，聚焦单店产值和有效门店占比提升，优化网点结构。 | U28: ≥368 | V28: 90 | W28: 固定90分（满分） | X28: 网点数量处于同类经销商中的领先水平，网点覆盖广泛，网络基础扎实。建议重点提升单店产值和核心店占比，优化网点质量；同时建立网点分级管理体系，提高网点运营效率。 | Z28: 超特|1000W-2000W|网点数量
A29: 超特 | B29: 1000W-2000W | C29: 增长层 | D29: 分销 | E29: 核心店数量占比 | F29: % | G29: 0.045 | H29: 0.187 | I29: 0.072 | J29: 30 | K29: 固定30分 | L29: 核心店数量占比处于同类经销商中的末位水平，分销渠道结构极不稳定，核心网点建设严重不足，增长依赖低产值网点。建议分级管理，紧急选拔有潜力门店进行重点培育，打造核心店；学习优秀经销商核心店建设经验，快速复制；建立核心店建设专项考核机制，确保建设效果。 | M29: 0.108 | N29: 50 | O29: 固定50分 | P29: 核心店数量占比处于同类经销商中的中等偏下水平，分销渠道结构不稳定，核心网点建设不足，市场支撑能力弱。建议持续提升网点质量，建立核心店运营标准，培育更多核心店。 | Q29: 0.187 | R29: 70 | S29: 固定70分 | T29: 核心店数量占比处于同类经销商中的中等偏上水平，分销渠道结构稳定，核心店占比相对健康。建议关注核心店达成，建立核心店培育与退出机制，持续提升核心店质量，稳定增长基础。 | U29: ≥18.7% | V29: 90 | W29: 固定90分（满分） | X29: 核心店数量占比处于同类经销商中的领先水平，核心资源集中，分销渠道增长由核心店驱动，市场竞争力强。建议持续关注核心店达成情况，保持增长动力。 | Z29: 超特|1000W-2000W|核心店数量占比
A30: 超特 | B30: 1000W-2000W | C30: 增长层 | D30: 分销 | E30: 有效门店占比 | F30: % | G30: 0.09 | H30: 0.942 | I30: 0.889 | J30: 30 | K30: 固定30分 | L30: 有效门店占比处于同类经销商中的末位水平，建议安排专人定时进行拜访，完善分销管理流程；对低效门店进行全面评估，制定关停并转计划，集中资源提升保留门店的运营效率。 | M30: 0.915 | N30: 50 | O30: 固定50分 | P30: 有效门店占比处于同类经销商中的中等偏下水平，存在部分“沉睡”门店。建议提升拜访率，激活沉睡门店，避免分销资源浪费；同时对低效门店进行评估，制定整改或淘汰计划。 | Q30: 0.942 | R30: 70 | S30: 固定70分 | T30: 有效门店占比处于同类经销商中的中等偏上水平，网点拜访率及陈列合格率较高，大部分门店运营有效，存在少量低效门店。建议对低效门店进行整改或优化，提升整体有效性。 | U30: ≥94.2% | V30: 90 | W30: 固定90分（满分） | X30: 有效门店占比处于同类经销商中的领先水平，网点拜访率及陈列合格率高，资源利用效率高。建议关注高拜访率门店的产值表现。 | Z30: 超特|1000W-2000W|有效门店占比
A31: 超特 | B31: 1000W-2000W | C31: 增长层 | D31: 分销 | E31: 人均服务网点数 | F31: 个 | G31: 0.045 | H31: 85个 | I31: 46 | J31: 30 | K31: 固定30分 | L31: 人均服务网点数处于同类经销商中的末位水平，人员服务密度严重不足，单点人力服务成本高。建议重新设定人员服务网点考核指标，提升人员利用效率。 | M31: 62 | N31: 50 | O31: 固定50分 | P31: 人均服务网点数处于同类经销商中的中等偏下水平，单兵服务半径较小，人力资源利用不充分。建议提升网点数量，释放人员效能。 | Q31: 85 | R31: 70 | S31: 固定70分 | T31: 人均服务网点数处于同类经销商中的中等偏上水平，管理半径相对合理。建议持续关注人效，优化资源配置。 | U31: ≥85 | V31: 90 | W31: 固定90分（满分） | X31: 人均服务网点数处于同类经销商中的领先水平，单兵服务密度极高，人员负荷处于满载状态。建议关注人效，防止服务质量下降。 | Z31: 超特|1000W-2000W|人均服务网点数
